{
    "registryname": "industrial_oven",
    "localizedname": "Industrial oven",

    "parts": [
        {
            "x": -1,
            "y": 2,
            "z": 3,
            "elements": "modularmachinery:blockcasing@0"
        },
        {
            "x": -1,
            "y": 0,
            "z": 0,
            "elements": "modularmachinery:blockcasing@5"
        },
        {
            "x": 1,
            "y": 2,
            "z": 1,
            "elements": "modularmachinery:blockcasing@0"
        },
        {
            "x": -2,
            "y": 0,
            "z": 0,
            "elements": "modularmachinery:blockcasing@5"
        },
        {
            "x": 0,
            "y": 2,
            "z": 3,
            "elements": "modularmachinery:blockcasing@0"
        },
        {
            "x": 2,
            "y": 2,
            "z": 1,
            "elements": "modularmachinery:blockcasing@0"
        },
        {
            "x": 1,
            "y": 0,
            "z": 0,
            "elements": "modularmachinery:blockcasing@5"
        },
        {
            "x": -3,
            "y": 0,
            "z": 4,
            "elements": "modularmachinery:blockcasing@0"
        },
        {
            "x": 3,
            "y": 2,
            "z": 1,
            "elements": "modularmachinery:blockcasing@0"
        },
        {
            "x": 2,
            "y": 0,
            "z": 0,
            "elements": "modularmachinery:blockcasing@5"
        },
        {
            "x": -2,
            "y": 0,
            "z": 4,
            "elements": "modularmachinery:blockcasing@0"
        },
        {
            "x": -3,
            "y": 0,
            "z": 0,
            "elements": "modularmachinery:blockcasing@0"
        },
        {
            "x": 1,
            "y": 2,
            "z": 3,
            "elements": "modularmachinery:blockcasing@0"
        },
        {
            "x": 2,
            "y": 2,
            "z": 3,
            "elements": "modularmachinery:blockcasing@0"
        },
        {
            "x": 3,
            "y": 0,
            "z": 0,
            "elements": "modularmachinery:blockcasing@0"
        },
        {
            "x": -1,
            "y": 0,
            "z": 4,
            "elements": "modularmachinery:blockcasing@0"
        },
        {
            "x": 0,
            "y": 0,
            "z": 4,
            "elements": "modularmachinery:blockcasing@0"
        },
        {
            "x": 3,
            "y": 2,
            "z": 3,
            "elements": "modularmachinery:blockcasing@0"
        },
        {
            "x": 1,
            "y": 0,
            "z": 4,
            "elements": "modularmachinery:blockcasing@0"
        },
        {
            "x": 3,
            "y": 0,
            "z": 2,
            "elements": "modularmachinery:blockoutputbus"
        },
        {
            "x": 2,
            "y": 0,
            "z": 4,
            "elements":"modularmachinery:blockcasing@0"
        },
        {
            "x": 3,
            "y": 0,
            "z": 4,
            "elements": "modularmachinery:blockcasing@0"
        },
        {
            "x": 3,
            "y": -1,
            "z": 0,
            "elements": "modularmachinery:blockcasing@0"
        },
        {
            "x": -3,
            "y": 1,
            "z": 0,
            "elements": "modularmachinery:blockcasing@0"
        },
        {
            "x": 2,
            "y": -1,
            "z": 0,
            "elements": "modularmachinery:blockcasing@0"
        },
        {
            "x": 1,
            "y": -1,
            "z": 0,
            "elements": "modularmachinery:blockcasing@0"
        },
        {
            "x": -2,
            "y": 1,
            "z": 0,
            "elements": "modularmachinery:blockcasing@0"
        },
        {
            "x": 0,
            "y": -1,
            "z": 0,
            "elements": "modularmachinery:blockcasing@0"
        },
        {
            "x": -1,
            "y": 1,
            "z": 0,
            "elements": "modularmachinery:blockcasing@0"
        },
        {
            "x": -3,
            "y": 1,
            "z": 2,
            "elements": "modularmachinery:blockfluidinputhatch"
        },
        {
            "x": 0,
            "y": 1,
            "z": 0,
            "elements": "modularmachinery:blockenergyinputhatch"
        },
        {
            "x": -1,
            "y": -1,
            "z": 0,
            "elements": "modularmachinery:blockcasing@0"
        },
        {
            "x": -3,
            "y": -1,
            "z": 1,
            "elements": "modularmachinery:blockcasing@0"
        },
        {
            "x": -2,
            "y": -1,
            "z": 0,
            "elements": "modularmachinery:blockcasing@0"
        },
        {
            "x": -2,
            "y": -1,
            "z": 1,
            "elements": "modularmachinery:blockcasing@2"
        },
        {
            "x": -3,
            "y": 1,
            "z": 4,
            "elements": "modularmachinery:blockcasing@0"
        },
        {
            "x": 1,
            "y": 1,
            "z": 0,
            "elements": "modularmachinery:blockcasing@0"
        },
        {
            "x": 2,
            "y": 1,
            "z": 0,
            "elements": "modularmachinery:blockcasing@0"
        },
        {
            "x": -1,
            "y": -1,
            "z": 1,
            "elements": "modularmachinery:blockcasing@2"
        },
        {
            "x": -3,
            "y": -1,
            "z": 0,
            "elements": "modularmachinery:blockcasing@0"
        },
        {
            "x": -3,
            "y": -1,
            "z": 3,
            "elements": "modularmachinery:blockcasing@0"
        },
        {
            "x": -2,
            "y": 1,
            "z": 4,
            "elements": "modularmachinery:blockcasing@0"
        },
        {
            "x": 0,
            "y": -1,
            "z": 1,
            "elements": "modularmachinery:blockcasing@2"
        },
        {
            "x": -2,
            "y": -1,
            "z": 3,
            "elements": "modularmachinery:blockcasing@2"
        },
        {
            "x": -1,
            "y": 1,
            "z": 4,
            "elements": "modularmachinery:blockcasing@0"
        },
        {
            "x": 3,
            "y": 1,
            "z": 0,
            "elements": "modularmachinery:blockcasing@0"
        },
        {
            "x": 0,
            "y": 1,
            "z": 4,
            "elements": "modularmachinery:blockcasing@0"
        },
        {
            "x": 1,
            "y": -1,
            "z": 1,
            "elements": "modularmachinery:blockcasing@2"
        },
        {
            "x": -1,
            "y": -1,
            "z": 3,
            "elements": "modularmachinery:blockcasing@2"
        },
        {
            "x": 0,
            "y": -1,
            "z": 3,
            "elements": "modularmachinery:blockcasing@2"
        },
        {
            "x": 1,
            "y": 1,
            "z": 4,
            "elements": "modularmachinery:blockcasing@0"
        },
        {
            "x": 3,
            "y": 1,
            "z": 2,
            "elements": "modularmachinery:blockcasing@0"
        },
        {
            "x": 2,
            "y": -1,
            "z": 1,
            "elements": "modularmachinery:blockcasing@2"
        },
        {
            "x": 2,
            "y": 1,
            "z": 4,
            "elements": "modularmachinery:blockcasing@0"
        },
        {
            "x": 1,
            "y": -1,
            "z": 3,
            "elements": "modularmachinery:blockcasing@2"
        },
        {
            "x": 3,
            "y": -1,
            "z": 1,
            "elements": "modularmachinery:blockcasing@0"
        },
        {
            "x": 3,
            "y": 1,
            "z": 4,
            "elements": "modularmachinery:blockcasing@0"
        },
        {
            "x": 2,
            "y": -1,
            "z": 3,
            "elements": "modularmachinery:blockcasing@2"
        },
        {
            "x": 3,
            "y": -1,
            "z": 3,
            "elements": "modularmachinery:blockcasing@0"
        },
        {
            "x": -3,
            "y": 2,
            "z": 2,
            "elements": "modularmachinery:blockcasing@0"
        },
        {
            "x": -3,
            "y": 0,
            "z": 1,
            "elements": "modularmachinery:blockcasing@0"
        },
        {
            "x": -2,
            "y": 2,
            "z": 2,
            "elements": "modularmachinery:blockcasing@1"
        },
        {
            "x": -1,
            "y": 2,
            "z": 2,
            "elements": "modularmachinery:blockcasing@0"
        },
        {
            "x": 0,
            "y": 2,
            "z": 2,
            "elements": "modularmachinery:blockcasing@1"
        },
        {
            "x": -3,
            "y": 0,
            "z": 3,
            "elements": "modularmachinery:blockcasing@0"
        },
        {
            "x": 1,
            "y": 2,
            "z": 2,
            "elements": "modularmachinery:blockcasing@0"
        },
        {
            "x": 2,
            "y": 2,
            "z": 2,
            "elements": "modularmachinery:blockcasing@1"
        },
        {
            "x": 3,
            "y": 2,
            "z": 2,
            "elements": "modularmachinery:blockcasing@0"
        },
        {
            "x": 3,
            "y": 0,
            "z": 1,
            "elements": "modularmachinery:blockcasing@0"
        },
        {
            "x": 3,
            "y": 0,
            "z": 3,
            "elements": "modularmachinery:blockcasing@0"
        },
        {
            "x": -3,
            "y": 1,
            "z": 1,
            "elements": "modularmachinery:blockcasing@0"
        },
        {
            "x": -3,
            "y": 1,
            "z": 3,
            "elements": "modularmachinery:blockcasing@0"
        },
        {
            "x": -3,
            "y": -1,
            "z": 2,
            "elements": "modularmachinery:blockcasing@0"
        },
        {
            "x": -2,
            "y": -1,
            "z": 2,
            "elements": "modularmachinery:blockcasing@2"
        },
        {
            "x": -1,
            "y": -1,
            "z": 2,
            "elements": "modularmachinery:blockcasing@2"
        },
        {
            "x": -3,
            "y": -1,
            "z": 4,
            "elements": "modularmachinery:blockcasing@0"
        },
        {
            "x": 0,
            "y": -1,
            "z": 2,
            "elements": "modularmachinery:blockcasing@2"
        },
        {
            "x": -2,
            "y": -1,
            "z": 4,
            "elements": "modularmachinery:blockcasing@0"
        },
        {
            "x": 3,
            "y": 1,
            "z": 1,
            "elements": "modularmachinery:blockcasing@0"
        },
        {
            "x": 1,
            "y": -1,
            "z": 2,
            "elements": "modularmachinery:blockcasing@2"
        },
        {
            "x": -1,
            "y": -1,
            "z": 4,
            "elements": "modularmachinery:blockcasing@0"
        },
        {
            "x": 0,
            "y": -1,
            "z": 4,
            "elements": "modularmachinery:blockcasing@0"
        },
        {
            "x": 3,
            "y": 1,
            "z": 3,
            "elements": "modularmachinery:blockcasing@0"
        },
        {
            "x": 2,
            "y": -1,
            "z": 2,
            "elements": "modularmachinery:blockcasing@2"
        },
        {
            "x": 1,
            "y": -1,
            "z": 4,
            "elements": "modularmachinery:blockcasing@0"
        },
        {
            "x": 3,
            "y": -1,
            "z": 2,
            "elements": "modularmachinery:blockcasing@0"
        },
        {
            "x": 2,
            "y": -1,
            "z": 4,
            "elements": "modularmachinery:blockcasing@0"
        },
        {
            "x": 3,
            "y": -1,
            "z": 4,
            "elements": "modularmachinery:blockcasing@0"
        },
        {
            "x": -3,
            "y": 2,
            "z": 1,
            "elements": "modularmachinery:blockcasing@0"
        },
        {
            "x": -2,
            "y": 2,
            "z": 1,
            "elements": "modularmachinery:blockcasing@0"
        },
        {
            "x": -1,
            "y": 2,
            "z": 1,
            "elements": "modularmachinery:blockcasing@0"
        },
        {
            "x": -3,
            "y": 2,
            "z": 3,
            "elements": "modularmachinery:blockcasing@0"
        },
        {
            "x": 0,
            "y": 2,
            "z": 1,
            "elements": "modularmachinery:blockcasing@0"
        },
        {
            "x": -3,
            "y": 0,
            "z": 2,
            "elements": "modularmachinery:blockinputbus"
        },
        {
            "x": -2,
            "y": 2,
            "z": 3,
            "elements": "modularmachinery:blockcasing@0"
        }
    ]}