{
    "registryname": "aircoolersmall",
    "localizedname": "Air Cooler (Small)",
    "color": "D7D7D7",
    "parts": [
        {
            "x": -2,
            "y": 0,
            "z": 2,
            "elements": [
                "immersiveengineering:sheetmetal@9"
            ]
        },
        {
            "x": -1,
            "y": 0,
            "z": 0,
            "elements": [
                "immersiveengineering:sheetmetal@9"
            ]
        },
        {
            "x": -2,
            "y": 0,
            "z": 0,
            "elements": [
                "immersiveengineering:sheetmetal@9"
            ]
        },
        {
            "x": 2,
            "y": 2,
            "z": 1,
            "elements": [
                "immersiveengineering:sheetmetal@9"
            ]
        },
        {
            "x": 1,
            "y": 0,
            "z": 0,
            "elements": [
                "immersiveengineering:sheetmetal@9"
            ]
        },
        {
            "x": -1,
            "y": 0,
            "z": 2,
            "elements": [
                "immersiveengineering:metal_decoration1@0"
            ]
        },
        {
            "x": 0,
            "y": 0,
            "z": 2,
            "elements": [
                "immersiveengineering:metal_decoration0@2"
            ]
        },
        {
            "x": 2,
            "y": 0,
            "z": 0,
            "elements": [
                "immersiveengineering:sheetmetal@9"
            ]
        },
        {
            "x": -2,
            "y": 0,
            "z": 4,
            "elements": [
                "immersiveengineering:sheetmetal@9"
            ]
        },
        {
            "x": 2,
            "y": 2,
            "z": 3,
            "elements": [
                "immersiveengineering:sheetmetal@9"
            ]
        },
        {
            "x": 1,
            "y": 0,
            "z": 2,
            "elements": [
                "immersiveengineering:metal_decoration1@0"
            ]
        },
        {
            "x": -1,
            "y": 0,
            "z": 4,
            "elements": [
                "immersiveengineering:sheetmetal@9"
            ]
        },
        {
            "x": 2,
            "y": 0,
            "z": 2,
            "elements": [
                "immersiveengineering:sheetmetal@9"
            ]
        },
        {
            "x": 0,
            "y": 0,
            "z": 4,
            "elements": [
                "modularmachinery:blockenergyinputhatch"
            ]
        },
        {
            "x": 1,
            "y": 0,
            "z": 4,
            "elements": [
                "immersiveengineering:sheetmetal@9"
            ]
        },
        {
            "x": 2,
            "y": 0,
            "z": 4,
            "elements": [
                "immersiveengineering:sheetmetal@9"
            ]
        },
        {
            "x": 2,
            "y": -1,
            "z": 0,
            "elements": [
                "industrialrenewal:catwalk_steel_pillar@0"
            ]
        },
        {
            "x": 1,
            "y": -1,
            "z": 0,
            "elements": [
                "industrialrenewal:catwalk_column_steel@0"
            ]
        },
        {
            "x": -2,
            "y": 1,
            "z": 0,
            "elements": [
                "immersiveengineering:sheetmetal@9"
            ]
        },
        {
            "x": -1,
            "y": 3,
            "z": 1,
            "elements": [
                "immersiveengineering:sheetmetal@9"
            ]
        },
        {
            "x": 0,
            "y": -1,
            "z": 0,
            "elements": [
                "industrialrenewal:catwalk_column_steel@0"
            ]
        },
        {
            "x": -1,
            "y": 1,
            "z": 0,
            "elements": [
                "immersiveengineering:sheetmetal@9"
            ]
        },
        {
            "x": 0,
            "y": 3,
            "z": 1,
            "elements": [
                "immersiveengineering:sheetmetal@9"
            ]
        },
        {
            "x": 1,
            "y": 3,
            "z": 1,
            "elements": [
                "immersiveengineering:sheetmetal@9"
            ]
        },
        {
            "x": 0,
            "y": 1,
            "z": 0,
            "elements": [
                "modularmachinery:blockfluidinputhatch"
            ]
        },
        {
            "x": -1,
            "y": -1,
            "z": 0,
            "elements": [
                "industrialrenewal:catwalk_column_steel@0"
            ]
        },
        {
            "x": -2,
            "y": 1,
            "z": 2,
            "elements": [
                "immersiveengineering:sheetmetal@9"
            ]
        },
        {
            "x": -1,
            "y": 3,
            "z": 3,
            "elements": [
                "immersiveengineering:sheetmetal@9"
            ]
        },
        {
            "x": -2,
            "y": -1,
            "z": 0,
            "elements": [
                "industrialrenewal:catwalk_steel_pillar@0"
            ]
        },
        {
            "x": -2,
            "y": -1,
            "z": 1,
            "elements": [
                "industrialrenewal:catwalk_column_steel@0"
            ]
        },
        {
            "x": -1,
            "y": 1,
            "z": 2,
            "elements": [
                "immersiveengineering:metal_device1@6"
            ]
        },
        {
            "x": 0,
            "y": 3,
            "z": 3,
            "elements": [
                "immersiveengineering:sheetmetal@9"
            ]
        },
        {
            "x": 1,
            "y": 1,
            "z": 0,
            "elements": [
                "immersiveengineering:sheetmetal@9"
            ]
        },
        {
            "x": 1,
            "y": 3,
            "z": 3,
            "elements": [
                "immersiveengineering:sheetmetal@9"
            ]
        },
        {
            "x": 2,
            "y": 1,
            "z": 0,
            "elements": [
                "immersiveengineering:sheetmetal@9"
            ]
        },
        {
            "x": -2,
            "y": 1,
            "z": 4,
            "elements": [
                "immersiveengineering:sheetmetal@9"
            ]
        },
        {
            "x": -2,
            "y": -1,
            "z": 3,
            "elements": [
                "industrialrenewal:catwalk_column_steel@0"
            ]
        },
        {
            "x": -1,
            "y": 1,
            "z": 4,
            "elements": [
                "immersiveengineering:sheetmetal@9"
            ]
        },
        {
            "x": 1,
            "y": 1,
            "z": 2,
            "elements": [
                "immersiveengineering:metal_device1@6"
            ]
        },
        {
            "x": 0,
            "y": 1,
            "z": 4,
            "elements": [
                "modularmachinery:blockfluidoutputhatch"
            ]
        },
        {
            "x": 2,
            "y": 1,
            "z": 2,
            "elements": [
                "immersiveengineering:sheetmetal@9"
            ]
        },
        {
            "x": 1,
            "y": 1,
            "z": 4,
            "elements": [
                "immersiveengineering:sheetmetal@9"
            ]
        },
        {
            "x": 2,
            "y": -1,
            "z": 1,
            "elements": [
                "industrialrenewal:catwalk_column_steel@0"
            ]
        },
        {
            "x": 2,
            "y": 1,
            "z": 4,
            "elements": [
                "immersiveengineering:sheetmetal@9"
            ]
        },
        {
            "x": 2,
            "y": -1,
            "z": 3,
            "elements": [
                "industrialrenewal:catwalk_column_steel@0"
            ]
        },
        {
            "x": 2,
            "y": -2,
            "z": 0,
            "elements": [
                "industrialrenewal:catwalk_steel_pillar@0"
            ]
        },
        {
            "x": -2,
            "y": 2,
            "z": 0,
            "elements": [
                "immersiveengineering:sheetmetal@9"
            ]
        },
        {
            "x": -1,
            "y": 2,
            "z": 0,
            "elements": [
                "immersiveengineering:sheetmetal@9"
            ]
        },
        {
            "x": 0,
            "y": 2,
            "z": 0,
            "elements": [
                "immersiveengineering:sheetmetal@9"
            ]
        },
        {
            "x": -2,
            "y": 2,
            "z": 2,
            "elements": [
                "immersiveengineering:sheetmetal@9"
            ]
        },
        {
            "x": -2,
            "y": 0,
            "z": 1,
            "elements": [
                "immersiveengineering:sheetmetal@9"
            ]
        },
        {
            "x": -2,
            "y": -2,
            "z": 0,
            "elements": [
                "industrialrenewal:catwalk_steel_pillar@0"
            ]
        },
        {
            "x": 1,
            "y": 2,
            "z": 0,
            "elements": [
                "immersiveengineering:sheetmetal@9"
            ]
        },
        {
            "x": 2,
            "y": 2,
            "z": 0,
            "elements": [
                "immersiveengineering:sheetmetal@9"
            ]
        },
        {
            "x": -2,
            "y": 2,
            "z": 4,
            "elements": [
                "immersiveengineering:sheetmetal@9"
            ]
        },
        {
            "x": 0,
            "y": 0,
            "z": 1,
            "elements": [
                "immersiveengineering:metal_decoration1@0"
            ]
        },
        {
            "x": -2,
            "y": 0,
            "z": 3,
            "elements": [
                "immersiveengineering:sheetmetal@9"
            ]
        },
        {
            "x": -1,
            "y": 2,
            "z": 4,
            "elements": [
                "immersiveengineering:sheetmetal@9"
            ]
        },
        {
            "x": 0,
            "y": 2,
            "z": 4,
            "elements": [
                "immersiveengineering:sheetmetal@9"
            ]
        },
        {
            "x": 2,
            "y": 2,
            "z": 2,
            "elements": [
                "immersiveengineering:sheetmetal@9"
            ]
        },
        {
            "x": 2,
            "y": 0,
            "z": 1,
            "elements": [
                "immersiveengineering:sheetmetal@9"
            ]
        },
        {
            "x": 0,
            "y": 0,
            "z": 3,
            "elements": [
                "immersiveengineering:metal_decoration1@0"
            ]
        },
        {
            "x": 1,
            "y": 2,
            "z": 4,
            "elements": [
                "immersiveengineering:sheetmetal@9"
            ]
        },
        {
            "x": 2,
            "y": 2,
            "z": 4,
            "elements": [
                "immersiveengineering:sheetmetal@9"
            ]
        },
        {
            "x": -2,
            "y": -2,
            "z": 4,
            "elements": [
                "industrialrenewal:catwalk_steel_pillar@0"
            ]
        },
        {
            "x": 2,
            "y": 0,
            "z": 3,
            "elements": [
                "immersiveengineering:sheetmetal@9"
            ]
        },
        {
            "x": 2,
            "y": -2,
            "z": 4,
            "elements": [
                "industrialrenewal:catwalk_steel_pillar@0"
            ]
        },
        {
            "x": -2,
            "y": 1,
            "z": 1,
            "elements": [
                "immersiveengineering:sheetmetal@9"
            ]
        },
        {
            "x": -1,
            "y": 3,
            "z": 2,
            "elements": [
                "immersiveengineering:sheetmetal@9"
            ]
        },
        {
            "x": -1,
            "y": 1,
            "z": 1,
            "elements": [
                "immersiveengineering:metal_device1@6"
            ]
        },
        {
            "x": 1,
            "y": 3,
            "z": 2,
            "elements": [
                "immersiveengineering:sheetmetal@9"
            ]
        },
        {
            "x": 0,
            "y": 1,
            "z": 1,
            "elements": [
                "immersiveengineering:metal_device1@6"
            ]
        },
        {
            "x": -2,
            "y": 1,
            "z": 3,
            "elements": [
                "immersiveengineering:sheetmetal@9"
            ]
        },
        {
            "x": -2,
            "y": -1,
            "z": 2,
            "elements": [
                "industrialrenewal:catwalk_column_steel@0"
            ]
        },
        {
            "x": -1,
            "y": 1,
            "z": 3,
            "elements": [
                "immersiveengineering:metal_device1@6"
            ]
        },
        {
            "x": 1,
            "y": 1,
            "z": 1,
            "elements": [
                "immersiveengineering:metal_device1@6"
            ]
        },
        {
            "x": 0,
            "y": 1,
            "z": 3,
            "elements": [
                "immersiveengineering:metal_device1@6"
            ]
        },
        {
            "x": 2,
            "y": 1,
            "z": 1,
            "elements": [
                "immersiveengineering:sheetmetal@9"
            ]
        },
        {
            "x": -2,
            "y": -1,
            "z": 4,
            "elements": [
                "industrialrenewal:catwalk_steel_pillar@0"
            ]
        },
        {
            "x": 1,
            "y": 1,
            "z": 3,
            "elements": [
                "immersiveengineering:metal_device1@6"
            ]
        },
        {
            "x": 2,
            "y": 1,
            "z": 3,
            "elements": [
                "immersiveengineering:sheetmetal@9"
            ]
        },
        {
            "x": -1,
            "y": -1,
            "z": 4,
            "elements": [
                "industrialrenewal:catwalk_column_steel@0"
            ]
        },
        {
            "x": 0,
            "y": -1,
            "z": 4,
            "elements": [
                "industrialrenewal:catwalk_column_steel@0"
            ]
        },
        {
            "x": 2,
            "y": -1,
            "z": 2,
            "elements": [
                "industrialrenewal:catwalk_column_steel@0"
            ]
        },
        {
            "x": 1,
            "y": -1,
            "z": 4,
            "elements": [
                "industrialrenewal:catwalk_column_steel@0"
            ]
        },
        {
            "x": 2,
            "y": -1,
            "z": 4,
            "elements": [
                "industrialrenewal:catwalk_steel_pillar@0"
            ]
        },
        {
            "x": -2,
            "y": 2,
            "z": 1,
            "elements": [
                "immersiveengineering:sheetmetal@9"
            ]
        },
        {
            "x": -2,
            "y": 2,
            "z": 3,
            "elements": [
                "immersiveengineering:sheetmetal@9"
            ]
        }
    ]}