{
    "registryname": "amineabslarge",
    "localizedname": "Amine Absorber Column (Large)",
    "color": "F3FAFF",
    "parts": [
        {
            "x": -1,
            "y": 0,
            "z": 0,
            "elements": [
                "immersiveengineering:sheetmetal@1"
            ]
        },
        {
            "x": 3,
            "y": 4,
            "z": 2,
            "elements": [
                "immersiveengineering:sheetmetal@1"
            ]
        },
        {
            "x": 2,
            "y": 2,
            "z": 1,
            "elements": [
                "immersiveengineering:sheetmetal@1"
            ]
        },
        {
            "x": 1,
            "y": 0,
            "z": 0,
            "elements": [
                "immersiveengineering:sheetmetal@1"
            ]
        },
        {
            "x": -1,
            "y": 21,
            "z": 2,
            "elements": [
                "immersiveengineering:sheetmetal@1"
            ]
        },
        {
            "x": 0,
            "y": 21,
            "z": 2,
            "elements": [
                "immersiveengineering:sheetmetal@1"
            ]
        },
        {
            "x": -1,
            "y": 19,
            "z": 1,
            "elements": [
                "immersiveengineering:sheetmetal@1"
            ]
        },
        {
            "x": 1,
            "y": 21,
            "z": 2,
            "elements": [
                "immersiveengineering:sheetmetal@1"
            ]
        },
        {
            "x": 0,
            "y": 19,
            "z": 1,
            "elements": [
                "immersiveengineering:sheetmetal@1"
            ]
        },
        {
            "x": 1,
            "y": 19,
            "z": 1,
            "elements": [
                "immersiveengineering:sheetmetal@1"
            ]
        },
        {
            "x": -2,
            "y": 9,
            "z": 4,
            "elements": [
                "immersiveengineering:sheetmetal@1"
            ]
        },
        {
            "x": -1,
            "y": 11,
            "z": 5,
            "elements": [
                "immersiveengineering:sheetmetal@1"
            ]
        },
        {
            "x": -3,
            "y": 5,
            "z": 2,
            "elements": [
                "immersiveengineering:sheetmetal@1"
            ]
        },
        {
            "x": -2,
            "y": 7,
            "z": 3,
            "elements": [
                "immersiveengineering:sheetmetal@1"
            ]
        },
        {
            "x": -1,
            "y": 9,
            "z": 4,
            "elements": [
                "contenttweaker:columninternal@0"
            ]
        },
        {
            "x": 0,
            "y": 11,
            "z": 5,
            "elements": [
                "immersiveengineering:sheetmetal@1"
            ]
        },
        {
            "x": -2,
            "y": 5,
            "z": 2,
            "elements": [
                "immersiveengineering:sheetmetal@1"
            ]
        },
        {
            "x": 1,
            "y": 11,
            "z": 5,
            "elements": [
                "immersiveengineering:sheetmetal@1"
            ]
        },
        {
            "x": 0,
            "y": 9,
            "z": 4,
            "elements": [
                "contenttweaker:columninternal@0"
            ]
        },
        {
            "x": 1,
            "y": 9,
            "z": 4,
            "elements": [
                "contenttweaker:columninternal@0"
            ]
        },
        {
            "x": -2,
            "y": 3,
            "z": 1,
            "elements": [
                "immersiveengineering:sheetmetal@1"
            ]
        },
        {
            "x": -1,
            "y": 5,
            "z": 2,
            "elements": [
                "contenttweaker:columninternal@0"
            ]
        },
        {
            "x": 2,
            "y": 9,
            "z": 4,
            "elements": [
                "immersiveengineering:sheetmetal@1"
            ]
        },
        {
            "x": 0,
            "y": 5,
            "z": 2,
            "elements": [
                "contenttweaker:columninternal@0"
            ]
        },
        {
            "x": 2,
            "y": 7,
            "z": 3,
            "elements": [
                "immersiveengineering:sheetmetal@1"
            ]
        },
        {
            "x": 1,
            "y": 5,
            "z": 2,
            "elements": [
                "contenttweaker:columninternal@0"
            ]
        },
        {
            "x": -1,
            "y": 1,
            "z": 0,
            "elements": [
                "immersiveengineering:sheetmetal@1"
            ]
        },
        {
            "x": 2,
            "y": 5,
            "z": 2,
            "elements": [
                "immersiveengineering:sheetmetal@1"
            ]
        },
        {
            "x": 0,
            "y": 1,
            "z": 0,
            "elements": [
                "immersiveengineering:sheetmetal@1"
            ]
        },
        {
            "x": 3,
            "y": 5,
            "z": 2,
            "elements": [
                "immersiveengineering:sheetmetal@1"
            ]
        },
        {
            "x": 2,
            "y": 3,
            "z": 1,
            "elements": [
                "immersiveengineering:sheetmetal@1"
            ]
        },
        {
            "x": 1,
            "y": 1,
            "z": 0,
            "elements": [
                "immersiveengineering:sheetmetal@1"
            ]
        },
        {
            "x": -1,
            "y": 20,
            "z": 1,
            "elements": [
                "immersiveengineering:sheetmetal@1"
            ]
        },
        {
            "x": 0,
            "y": 20,
            "z": 1,
            "elements": [
                "immersiveengineering:sheetmetal@1"
            ]
        },
        {
            "x": 1,
            "y": 20,
            "z": 1,
            "elements": [
                "immersiveengineering:sheetmetal@1"
            ]
        },
        {
            "x": -2,
            "y": 10,
            "z": 4,
            "elements": [
                "immersiveengineering:sheetmetal@1"
            ]
        },
        {
            "x": -1,
            "y": 12,
            "z": 5,
            "elements": [
                "immersiveengineering:sheetmetal@1"
            ]
        },
        {
            "x": -2,
            "y": 8,
            "z": 3,
            "elements": [
                "immersiveengineering:sheetmetal@1"
            ]
        },
        {
            "x": 0,
            "y": 12,
            "z": 5,
            "elements": [
                "immersiveengineering:sheetmetal@1"
            ]
        },
        {
            "x": -2,
            "y": 6,
            "z": 2,
            "elements": [
                "immersiveengineering:sheetmetal@1"
            ]
        },
        {
            "x": 1,
            "y": 12,
            "z": 5,
            "elements": [
                "immersiveengineering:sheetmetal@1"
            ]
        },
        {
            "x": -2,
            "y": 4,
            "z": 1,
            "elements": [
                "immersiveengineering:sheetmetal@1"
            ]
        },
        {
            "x": 2,
            "y": 10,
            "z": 4,
            "elements": [
                "immersiveengineering:sheetmetal@1"
            ]
        },
        {
            "x": 2,
            "y": 8,
            "z": 3,
            "elements": [
                "immersiveengineering:sheetmetal@1"
            ]
        },
        {
            "x": -1,
            "y": 2,
            "z": 0,
            "elements": [
                "immersiveengineering:sheetmetal@1"
            ]
        },
        {
            "x": 2,
            "y": 6,
            "z": 2,
            "elements": [
                "immersiveengineering:sheetmetal@1"
            ]
        },
        {
            "x": 0,
            "y": 2,
            "z": 0,
            "elements": [
                "immersiveengineering:sheetmetal@1"
            ]
        },
        {
            "x": 2,
            "y": 4,
            "z": 1,
            "elements": [
                "immersiveengineering:sheetmetal@1"
            ]
        },
        {
            "x": 1,
            "y": 2,
            "z": 0,
            "elements": [
                "immersiveengineering:sheetmetal@1"
            ]
        },
        {
            "x": -2,
            "y": 11,
            "z": 4,
            "elements": [
                "immersiveengineering:sheetmetal@1"
            ]
        },
        {
            "x": -1,
            "y": 13,
            "z": 5,
            "elements": [
                "immersiveengineering:sheetmetal@1"
            ]
        },
        {
            "x": -2,
            "y": 9,
            "z": 3,
            "elements": [
                "immersiveengineering:sheetmetal@1"
            ]
        },
        {
            "x": 0,
            "y": 13,
            "z": 5,
            "elements": [
                "immersiveengineering:sheetmetal@1"
            ]
        },
        {
            "x": -2,
            "y": 7,
            "z": 2,
            "elements": [
                "immersiveengineering:sheetmetal@1"
            ]
        },
        {
            "x": -1,
            "y": 9,
            "z": 3,
            "elements": [
                "contenttweaker:columninternal@0"
            ]
        },
        {
            "x": 1,
            "y": 13,
            "z": 5,
            "elements": [
                "immersiveengineering:sheetmetal@1"
            ]
        },
        {
            "x": -2,
            "y": 5,
            "z": 1,
            "elements": [
                "immersiveengineering:sheetmetal@1"
            ]
        },
        {
            "x": 0,
            "y": 9,
            "z": 3,
            "elements": [
                "contenttweaker:columninternal@0"
            ]
        },
        {
            "x": 2,
            "y": 11,
            "z": 4,
            "elements": [
                "immersiveengineering:sheetmetal@1"
            ]
        },
        {
            "x": 1,
            "y": 9,
            "z": 3,
            "elements": [
                "contenttweaker:columninternal@0"
            ]
        },
        {
            "x": -1,
            "y": 5,
            "z": 1,
            "elements": [
                "immersiveengineering:sheetmetal@1"
            ]
        },
        {
            "x": 2,
            "y": 9,
            "z": 3,
            "elements": [
                "immersiveengineering:sheetmetal@1"
            ]
        },
        {
            "x": 0,
            "y": 5,
            "z": 1,
            "elements": [
                "immersiveengineering:sheetmetal@1"
            ]
        },
        {
            "x": -1,
            "y": 3,
            "z": 0,
            "elements": [
                "immersiveengineering:sheetmetal@1"
            ]
        },
        {
            "x": 2,
            "y": 7,
            "z": 2,
            "elements": [
                "immersiveengineering:sheetmetal@1"
            ]
        },
        {
            "x": 1,
            "y": 5,
            "z": 1,
            "elements": [
                "immersiveengineering:sheetmetal@1"
            ]
        },
        {
            "x": 0,
            "y": 3,
            "z": 0,
            "elements": [
                "immersiveengineering:sheetmetal@1"
            ]
        },
        {
            "x": 2,
            "y": 5,
            "z": 1,
            "elements": [
                "immersiveengineering:sheetmetal@1"
            ]
        },
        {
            "x": 1,
            "y": 3,
            "z": 0,
            "elements": [
                "immersiveengineering:sheetmetal@1"
            ]
        },
        {
            "x": -2,
            "y": 12,
            "z": 4,
            "elements": [
                "immersiveengineering:sheetmetal@1"
            ]
        },
        {
            "x": -1,
            "y": 14,
            "z": 5,
            "elements": [
                "immersiveengineering:sheetmetal@1"
            ]
        },
        {
            "x": -2,
            "y": 10,
            "z": 3,
            "elements": [
                "immersiveengineering:sheetmetal@1"
            ]
        },
        {
            "x": 0,
            "y": 14,
            "z": 5,
            "elements": [
                "immersiveengineering:sheetmetal@1"
            ]
        },
        {
            "x": -2,
            "y": 8,
            "z": 2,
            "elements": [
                "immersiveengineering:sheetmetal@1"
            ]
        },
        {
            "x": 1,
            "y": 14,
            "z": 5,
            "elements": [
                "immersiveengineering:sheetmetal@1"
            ]
        },
        {
            "x": 2,
            "y": 12,
            "z": 4,
            "elements": [
                "immersiveengineering:sheetmetal@1"
            ]
        },
        {
            "x": -1,
            "y": 6,
            "z": 1,
            "elements": [
                "immersiveengineering:sheetmetal@1"
            ]
        },
        {
            "x": 2,
            "y": 10,
            "z": 3,
            "elements": [
                "immersiveengineering:sheetmetal@1"
            ]
        },
        {
            "x": 0,
            "y": 6,
            "z": 1,
            "elements": [
                "immersiveengineering:sheetmetal@1"
            ]
        },
        {
            "x": -1,
            "y": 4,
            "z": 0,
            "elements": [
                "immersiveengineering:sheetmetal@1"
            ]
        },
        {
            "x": 2,
            "y": 8,
            "z": 2,
            "elements": [
                "immersiveengineering:sheetmetal@1"
            ]
        },
        {
            "x": 1,
            "y": 6,
            "z": 1,
            "elements": [
                "immersiveengineering:sheetmetal@1"
            ]
        },
        {
            "x": 0,
            "y": 4,
            "z": 0,
            "elements": [
                "immersiveengineering:sheetmetal@1"
            ]
        },
        {
            "x": 1,
            "y": 4,
            "z": 0,
            "elements": [
                "immersiveengineering:sheetmetal@1"
            ]
        },
        {
            "x": -1,
            "y": 0,
            "z": 6,
            "elements": [
                "immersiveengineering:sheetmetal@1"
            ]
        },
        {
            "x": 0,
            "y": 0,
            "z": 6,
            "elements": [
                "immersiveengineering:sheetmetal@1"
            ]
        },
        {
            "x": 1,
            "y": 0,
            "z": 6,
            "elements": [
                "immersiveengineering:sheetmetal@1"
            ]
        },
        {
            "x": -2,
            "y": 13,
            "z": 4,
            "elements": [
                "immersiveengineering:sheetmetal@1"
            ]
        },
        {
            "x": -1,
            "y": 15,
            "z": 5,
            "elements": [
                "immersiveengineering:sheetmetal@1"
            ]
        },
        {
            "x": -2,
            "y": 11,
            "z": 3,
            "elements": [
                "immersiveengineering:sheetmetal@1"
            ]
        },
        {
            "x": 0,
            "y": 15,
            "z": 5,
            "elements": [
                "immersiveengineering:sheetmetal@1"
            ]
        },
        {
            "x": -2,
            "y": 9,
            "z": 2,
            "elements": [
                "immersiveengineering:sheetmetal@1"
            ]
        },
        {
            "x": 1,
            "y": 15,
            "z": 5,
            "elements": [
                "immersiveengineering:sheetmetal@1"
            ]
        },
        {
            "x": -1,
            "y": 7,
            "z": 1,
            "elements": [
                "immersiveengineering:sheetmetal@1"
            ]
        },
        {
            "x": 2,
            "y": 13,
            "z": 4,
            "elements": [
                "immersiveengineering:sheetmetal@1"
            ]
        },
        {
            "x": 2,
            "y": 11,
            "z": 3,
            "elements": [
                "immersiveengineering:sheetmetal@1"
            ]
        },
        {
            "x": 0,
            "y": 7,
            "z": 1,
            "elements": [
                "modularmachinery:blockfluidinputhatch"
            ]
        },
        {
            "x": -1,
            "y": 5,
            "z": 0,
            "elements": [
                "immersiveengineering:sheetmetal@1"
            ]
        },
        {
            "x": 2,
            "y": 9,
            "z": 2,
            "elements": [
                "immersiveengineering:sheetmetal@1"
            ]
        },
        {
            "x": 1,
            "y": 7,
            "z": 1,
            "elements": [
                "immersiveengineering:sheetmetal@1"
            ]
        },
        {
            "x": 0,
            "y": 5,
            "z": 0,
            "elements": [
                "immersiveengineering:sheetmetal@1"
            ]
        },
        {
            "x": 1,
            "y": 5,
            "z": 0,
            "elements": [
                "immersiveengineering:sheetmetal@1"
            ]
        },
        {
            "x": -1,
            "y": 1,
            "z": 6,
            "elements": [
                "immersiveengineering:sheetmetal@1"
            ]
        },
        {
            "x": 0,
            "y": 1,
            "z": 6,
            "elements": [
                "immersiveengineering:sheetmetal@1"
            ]
        },
        {
            "x": -1,
            "y": -1,
            "z": 5,
            "elements": [
                "immersiveengineering:sheetmetal@1"
            ]
        },
        {
            "x": 0,
            "y": -1,
            "z": 5,
            "elements": [
                "immersiveengineering:sheetmetal@1"
            ]
        },
        {
            "x": 1,
            "y": 1,
            "z": 6,
            "elements": [
                "immersiveengineering:sheetmetal@1"
            ]
        },
        {
            "x": 1,
            "y": -1,
            "z": 5,
            "elements": [
                "immersiveengineering:sheetmetal@1"
            ]
        },
        {
            "x": -2,
            "y": 14,
            "z": 4,
            "elements": [
                "immersiveengineering:sheetmetal@1"
            ]
        },
        {
            "x": -1,
            "y": 16,
            "z": 5,
            "elements": [
                "immersiveengineering:sheetmetal@1"
            ]
        },
        {
            "x": -2,
            "y": 12,
            "z": 3,
            "elements": [
                "immersiveengineering:sheetmetal@1"
            ]
        },
        {
            "x": 0,
            "y": 16,
            "z": 5,
            "elements": [
                "modularmachinery:blockfluidinputhatch"
            ]
        },
        {
            "x": -2,
            "y": 10,
            "z": 2,
            "elements": [
                "immersiveengineering:sheetmetal@1"
            ]
        },
        {
            "x": -1,
            "y": 12,
            "z": 3,
            "elements": [
                "contenttweaker:columninternal@0"
            ]
        },
        {
            "x": 1,
            "y": 16,
            "z": 5,
            "elements": [
                "immersiveengineering:sheetmetal@1"
            ]
        },
        {
            "x": 0,
            "y": 12,
            "z": 3,
            "elements": [
                "contenttweaker:columninternal@0"
            ]
        },
        {
            "x": -1,
            "y": 8,
            "z": 1,
            "elements": [
                "immersiveengineering:sheetmetal@1"
            ]
        },
        {
            "x": 2,
            "y": 14,
            "z": 4,
            "elements": [
                "immersiveengineering:sheetmetal@1"
            ]
        },
        {
            "x": 1,
            "y": 12,
            "z": 3,
            "elements": [
                "contenttweaker:columninternal@0"
            ]
        },
        {
            "x": 2,
            "y": 12,
            "z": 3,
            "elements": [
                "immersiveengineering:sheetmetal@1"
            ]
        },
        {
            "x": 0,
            "y": 8,
            "z": 1,
            "elements": [
                "immersiveengineering:sheetmetal@1"
            ]
        },
        {
            "x": 2,
            "y": 10,
            "z": 2,
            "elements": [
                "immersiveengineering:sheetmetal@1"
            ]
        },
        {
            "x": 1,
            "y": 8,
            "z": 1,
            "elements": [
                "immersiveengineering:sheetmetal@1"
            ]
        },
        {
            "x": -2,
            "y": 0,
            "z": 5,
            "elements": [
                "immersiveengineering:sheetmetal@1"
            ]
        },
        {
            "x": -1,
            "y": 2,
            "z": 6,
            "elements": [
                "immersiveengineering:sheetmetal@1"
            ]
        },
        {
            "x": 0,
            "y": 2,
            "z": 6,
            "elements": [
                "immersiveengineering:sheetmetal@1"
            ]
        },
        {
            "x": -1,
            "y": 0,
            "z": 5,
            "elements": [
                "immersiveengineering:sheetmetal@1"
            ]
        },
        {
            "x": 0,
            "y": 0,
            "z": 5,
            "elements": [
                "immersiveengineering:sheetmetal@1"
            ]
        },
        {
            "x": 1,
            "y": 2,
            "z": 6,
            "elements": [
                "immersiveengineering:sheetmetal@1"
            ]
        },
        {
            "x": 1,
            "y": 0,
            "z": 5,
            "elements": [
                "immersiveengineering:sheetmetal@1"
            ]
        },
        {
            "x": 2,
            "y": 0,
            "z": 5,
            "elements": [
                "immersiveengineering:sheetmetal@1"
            ]
        },
        {
            "x": -2,
            "y": 15,
            "z": 4,
            "elements": [
                "immersiveengineering:sheetmetal@1"
            ]
        },
        {
            "x": -1,
            "y": 17,
            "z": 5,
            "elements": [
                "immersiveengineering:sheetmetal@1"
            ]
        },
        {
            "x": 0,
            "y": 17,
            "z": 5,
            "elements": [
                "immersiveengineering:sheetmetal@1"
            ]
        },
        {
            "x": -2,
            "y": 13,
            "z": 3,
            "elements": [
                "immersiveengineering:sheetmetal@1"
            ]
        },
        {
            "x": -1,
            "y": 15,
            "z": 4,
            "elements": [
                "contenttweaker:columninternal@0"
            ]
        },
        {
            "x": -2,
            "y": 11,
            "z": 2,
            "elements": [
                "immersiveengineering:sheetmetal@1"
            ]
        },
        {
            "x": 1,
            "y": 17,
            "z": 5,
            "elements": [
                "immersiveengineering:sheetmetal@1"
            ]
        },
        {
            "x": 0,
            "y": 15,
            "z": 4,
            "elements": [
                "contenttweaker:columninternal@0"
            ]
        },
        {
            "x": 1,
            "y": 15,
            "z": 4,
            "elements": [
                "contenttweaker:columninternal@0"
            ]
        },
        {
            "x": -1,
            "y": 9,
            "z": 1,
            "elements": [
                "immersiveengineering:sheetmetal@1"
            ]
        },
        {
            "x": 2,
            "y": 15,
            "z": 4,
            "elements": [
                "immersiveengineering:sheetmetal@1"
            ]
        },
        {
            "x": 2,
            "y": 13,
            "z": 3,
            "elements": [
                "immersiveengineering:sheetmetal@1"
            ]
        },
        {
            "x": 0,
            "y": 9,
            "z": 1,
            "elements": [
                "immersiveengineering:sheetmetal@1"
            ]
        },
        {
            "x": 2,
            "y": 11,
            "z": 2,
            "elements": [
                "immersiveengineering:sheetmetal@1"
            ]
        },
        {
            "x": 1,
            "y": 9,
            "z": 1,
            "elements": [
                "immersiveengineering:sheetmetal@1"
            ]
        },
        {
            "x": -2,
            "y": 1,
            "z": 5,
            "elements": [
                "immersiveengineering:sheetmetal@1"
            ]
        },
        {
            "x": -1,
            "y": 3,
            "z": 6,
            "elements": [
                "immersiveengineering:sheetmetal@1"
            ]
        },
        {
            "x": 0,
            "y": 3,
            "z": 6,
            "elements": [
                "immersiveengineering:sheetmetal@1"
            ]
        },
        {
            "x": -2,
            "y": -1,
            "z": 4,
            "elements": [
                "immersiveengineering:sheetmetal@1"
            ]
        },
        {
            "x": 1,
            "y": 3,
            "z": 6,
            "elements": [
                "immersiveengineering:sheetmetal@1"
            ]
        },
        {
            "x": -1,
            "y": -1,
            "z": 4,
            "elements": [
                "immersiveengineering:sheetmetal@1"
            ]
        },
        {
            "x": 0,
            "y": -1,
            "z": 4,
            "elements": [
                "immersiveengineering:sheetmetal@1"
            ]
        },
        {
            "x": 2,
            "y": 1,
            "z": 5,
            "elements": [
                "immersiveengineering:sheetmetal@1"
            ]
        },
        {
            "x": 1,
            "y": -1,
            "z": 4,
            "elements": [
                "immersiveengineering:sheetmetal@1"
            ]
        },
        {
            "x": 2,
            "y": -1,
            "z": 4,
            "elements": [
                "immersiveengineering:sheetmetal@1"
            ]
        },
        {
            "x": -2,
            "y": 16,
            "z": 4,
            "elements": [
                "immersiveengineering:sheetmetal@1"
            ]
        },
        {
            "x": -1,
            "y": 18,
            "z": 5,
            "elements": [
                "immersiveengineering:sheetmetal@1"
            ]
        },
        {
            "x": 0,
            "y": 18,
            "z": 5,
            "elements": [
                "immersiveengineering:sheetmetal@1"
            ]
        },
        {
            "x": -2,
            "y": 14,
            "z": 3,
            "elements": [
                "immersiveengineering:sheetmetal@1"
            ]
        },
        {
            "x": -2,
            "y": 12,
            "z": 2,
            "elements": [
                "immersiveengineering:sheetmetal@1"
            ]
        },
        {
            "x": 1,
            "y": 18,
            "z": 5,
            "elements": [
                "immersiveengineering:sheetmetal@1"
            ]
        },
        {
            "x": -1,
            "y": 12,
            "z": 2,
            "elements": [
                "contenttweaker:columninternal@0"
            ]
        },
        {
            "x": -1,
            "y": 10,
            "z": 1,
            "elements": [
                "immersiveengineering:sheetmetal@1"
            ]
        },
        {
            "x": 2,
            "y": 16,
            "z": 4,
            "elements": [
                "immersiveengineering:sheetmetal@1"
            ]
        },
        {
            "x": 0,
            "y": 12,
            "z": 2,
            "elements": [
                "contenttweaker:columninternal@0"
            ]
        },
        {
            "x": 2,
            "y": 14,
            "z": 3,
            "elements": [
                "immersiveengineering:sheetmetal@1"
            ]
        },
        {
            "x": 1,
            "y": 12,
            "z": 2,
            "elements": [
                "contenttweaker:columninternal@0"
            ]
        },
        {
            "x": 0,
            "y": 10,
            "z": 1,
            "elements": [
                "immersiveengineering:sheetmetal@1"
            ]
        },
        {
            "x": 2,
            "y": 12,
            "z": 2,
            "elements": [
                "immersiveengineering:sheetmetal@1"
            ]
        },
        {
            "x": 1,
            "y": 10,
            "z": 1,
            "elements": [
                "immersiveengineering:sheetmetal@1"
            ]
        },
        {
            "x": -3,
            "y": 0,
            "z": 4,
            "elements": [
                "immersiveengineering:sheetmetal@1"
            ]
        },
        {
            "x": -2,
            "y": 2,
            "z": 5,
            "elements": [
                "immersiveengineering:sheetmetal@1"
            ]
        },
        {
            "x": -1,
            "y": 4,
            "z": 6,
            "elements": [
                "immersiveengineering:sheetmetal@1"
            ]
        },
        {
            "x": 0,
            "y": 4,
            "z": 6,
            "elements": [
                "immersiveengineering:sheetmetal@1"
            ]
        },
        {
            "x": -2,
            "y": 0,
            "z": 4,
            "elements": [
                "immersiveengineering:sheetmetal@1"
            ]
        },
        {
            "x": 1,
            "y": 4,
            "z": 6,
            "elements": [
                "immersiveengineering:sheetmetal@1"
            ]
        },
        {
            "x": 2,
            "y": 2,
            "z": 5,
            "elements": [
                "immersiveengineering:sheetmetal@1"
            ]
        },
        {
            "x": 2,
            "y": 0,
            "z": 4,
            "elements": [
                "immersiveengineering:sheetmetal@1"
            ]
        },
        {
            "x": 3,
            "y": 0,
            "z": 4,
            "elements": [
                "immersiveengineering:sheetmetal@1"
            ]
        },
        {
            "x": -2,
            "y": 17,
            "z": 4,
            "elements": [
                "immersiveengineering:sheetmetal@1"
            ]
        },
        {
            "x": -1,
            "y": 19,
            "z": 5,
            "elements": [
                "immersiveengineering:sheetmetal@1"
            ]
        },
        {
            "x": 0,
            "y": 19,
            "z": 5,
            "elements": [
                "immersiveengineering:sheetmetal@1"
            ]
        },
        {
            "x": -2,
            "y": 15,
            "z": 3,
            "elements": [
                "immersiveengineering:sheetmetal@1"
            ]
        },
        {
            "x": 1,
            "y": 19,
            "z": 5,
            "elements": [
                "immersiveengineering:sheetmetal@1"
            ]
        },
        {
            "x": -2,
            "y": 13,
            "z": 2,
            "elements": [
                "immersiveengineering:sheetmetal@1"
            ]
        },
        {
            "x": -1,
            "y": 15,
            "z": 3,
            "elements": [
                "contenttweaker:columninternal@0"
            ]
        },
        {
            "x": 0,
            "y": 15,
            "z": 3,
            "elements": [
                "contenttweaker:columninternal@0"
            ]
        },
        {
            "x": -1,
            "y": 11,
            "z": 1,
            "elements": [
                "immersiveengineering:sheetmetal@1"
            ]
        },
        {
            "x": 2,
            "y": 17,
            "z": 4,
            "elements": [
                "immersiveengineering:sheetmetal@1"
            ]
        },
        {
            "x": 1,
            "y": 15,
            "z": 3,
            "elements": [
                "contenttweaker:columninternal@0"
            ]
        },
        {
            "x": 2,
            "y": 15,
            "z": 3,
            "elements": [
                "immersiveengineering:sheetmetal@1"
            ]
        },
        {
            "x": 0,
            "y": 11,
            "z": 1,
            "elements": [
                "immersiveengineering:sheetmetal@1"
            ]
        },
        {
            "x": 2,
            "y": 13,
            "z": 2,
            "elements": [
                "immersiveengineering:sheetmetal@1"
            ]
        },
        {
            "x": 1,
            "y": 11,
            "z": 1,
            "elements": [
                "immersiveengineering:sheetmetal@1"
            ]
        },
        {
            "x": -3,
            "y": 1,
            "z": 4,
            "elements": [
                "immersiveengineering:sheetmetal@1"
            ]
        },
        {
            "x": -2,
            "y": 3,
            "z": 5,
            "elements": [
                "immersiveengineering:sheetmetal@1"
            ]
        },
        {
            "x": -1,
            "y": 5,
            "z": 6,
            "elements": [
                "immersiveengineering:sheetmetal@1"
            ]
        },
        {
            "x": 0,
            "y": 5,
            "z": 6,
            "elements": [
                "immersiveengineering:sheetmetal@1"
            ]
        },
        {
            "x": 1,
            "y": 5,
            "z": 6,
            "elements": [
                "immersiveengineering:sheetmetal@1"
            ]
        },
        {
            "x": -2,
            "y": -1,
            "z": 3,
            "elements": [
                "immersiveengineering:sheetmetal@1"
            ]
        },
        {
            "x": -1,
            "y": -1,
            "z": 3,
            "elements": [
                "immersiveengineering:sheetmetal@1"
            ]
        },
        {
            "x": 0,
            "y": -1,
            "z": 3,
            "elements": [
                "modularmachinery:blockfluidoutputhatch"
            ]
        },
        {
            "x": 2,
            "y": 3,
            "z": 5,
            "elements": [
                "immersiveengineering:sheetmetal@1"
            ]
        },
        {
            "x": 1,
            "y": -1,
            "z": 3,
            "elements": [
                "immersiveengineering:sheetmetal@1"
            ]
        },
        {
            "x": 3,
            "y": 1,
            "z": 4,
            "elements": [
                "immersiveengineering:sheetmetal@1"
            ]
        },
        {
            "x": 2,
            "y": -1,
            "z": 3,
            "elements": [
                "immersiveengineering:sheetmetal@1"
            ]
        },
        {
            "x": -2,
            "y": 18,
            "z": 4,
            "elements": [
                "immersiveengineering:sheetmetal@1"
            ]
        },
        {
            "x": -1,
            "y": 20,
            "z": 5,
            "elements": [
                "immersiveengineering:sheetmetal@1"
            ]
        },
        {
            "x": 0,
            "y": 20,
            "z": 5,
            "elements": [
                "immersiveengineering:sheetmetal@1"
            ]
        },
        {
            "x": -2,
            "y": 16,
            "z": 3,
            "elements": [
                "immersiveengineering:sheetmetal@1"
            ]
        },
        {
            "x": -1,
            "y": 18,
            "z": 4,
            "elements": [
                "contenttweaker:columninternal@0"
            ]
        },
        {
            "x": 1,
            "y": 20,
            "z": 5,
            "elements": [
                "immersiveengineering:sheetmetal@1"
            ]
        },
        {
            "x": 0,
            "y": 18,
            "z": 4,
            "elements": [
                "contenttweaker:columninternal@0"
            ]
        },
        {
            "x": -2,
            "y": 14,
            "z": 2,
            "elements": [
                "immersiveengineering:sheetmetal@1"
            ]
        },
        {
            "x": 1,
            "y": 18,
            "z": 4,
            "elements": [
                "contenttweaker:columninternal@0"
            ]
        },
        {
            "x": -1,
            "y": 12,
            "z": 1,
            "elements": [
                "immersiveengineering:sheetmetal@1"
            ]
        },
        {
            "x": 2,
            "y": 18,
            "z": 4,
            "elements": [
                "immersiveengineering:sheetmetal@1"
            ]
        },
        {
            "x": 2,
            "y": 16,
            "z": 3,
            "elements": [
                "immersiveengineering:sheetmetal@1"
            ]
        },
        {
            "x": 0,
            "y": 12,
            "z": 1,
            "elements": [
                "immersiveengineering:sheetmetal@1"
            ]
        },
        {
            "x": 2,
            "y": 14,
            "z": 2,
            "elements": [
                "immersiveengineering:sheetmetal@1"
            ]
        },
        {
            "x": 1,
            "y": 12,
            "z": 1,
            "elements": [
                "immersiveengineering:sheetmetal@1"
            ]
        },
        {
            "x": -3,
            "y": 2,
            "z": 4,
            "elements": [
                "immersiveengineering:sheetmetal@1"
            ]
        },
        {
            "x": -2,
            "y": 4,
            "z": 5,
            "elements": [
                "immersiveengineering:sheetmetal@1"
            ]
        },
        {
            "x": -3,
            "y": 0,
            "z": 3,
            "elements": [
                "immersiveengineering:sheetmetal@1"
            ]
        },
        {
            "x": -2,
            "y": 0,
            "z": 3,
            "elements": [
                "immersiveengineering:sheetmetal@1"
            ]
        },
        {
            "x": 2,
            "y": 4,
            "z": 5,
            "elements": [
                "immersiveengineering:sheetmetal@1"
            ]
        },
        {
            "x": 3,
            "y": 2,
            "z": 4,
            "elements": [
                "immersiveengineering:sheetmetal@1"
            ]
        },
        {
            "x": 2,
            "y": 0,
            "z": 3,
            "elements": [
                "immersiveengineering:sheetmetal@1"
            ]
        },
        {
            "x": 3,
            "y": 0,
            "z": 3,
            "elements": [
                "immersiveengineering:sheetmetal@1"
            ]
        },
        {
            "x": -2,
            "y": 19,
            "z": 4,
            "elements": [
                "immersiveengineering:sheetmetal@1"
            ]
        },
        {
            "x": -2,
            "y": 17,
            "z": 3,
            "elements": [
                "immersiveengineering:sheetmetal@1"
            ]
        },
        {
            "x": -2,
            "y": 15,
            "z": 2,
            "elements": [
                "immersiveengineering:sheetmetal@1"
            ]
        },
        {
            "x": -1,
            "y": 13,
            "z": 1,
            "elements": [
                "immersiveengineering:sheetmetal@1"
            ]
        },
        {
            "x": 2,
            "y": 19,
            "z": 4,
            "elements": [
                "immersiveengineering:sheetmetal@1"
            ]
        },
        {
            "x": 2,
            "y": 17,
            "z": 3,
            "elements": [
                "immersiveengineering:sheetmetal@1"
            ]
        },
        {
            "x": 0,
            "y": 13,
            "z": 1,
            "elements": [
                "immersiveengineering:sheetmetal@1"
            ]
        },
        {
            "x": 2,
            "y": 15,
            "z": 2,
            "elements": [
                "immersiveengineering:sheetmetal@1"
            ]
        },
        {
            "x": 1,
            "y": 13,
            "z": 1,
            "elements": [
                "immersiveengineering:sheetmetal@1"
            ]
        },
        {
            "x": -3,
            "y": 3,
            "z": 4,
            "elements": [
                "immersiveengineering:sheetmetal@1"
            ]
        },
        {
            "x": -2,
            "y": 5,
            "z": 5,
            "elements": [
                "immersiveengineering:sheetmetal@1"
            ]
        },
        {
            "x": -3,
            "y": 1,
            "z": 3,
            "elements": [
                "immersiveengineering:sheetmetal@1"
            ]
        },
        {
            "x": -1,
            "y": 5,
            "z": 5,
            "elements": [
                "immersiveengineering:sheetmetal@1"
            ]
        },
        {
            "x": 0,
            "y": 5,
            "z": 5,
            "elements": [
                "immersiveengineering:sheetmetal@1"
            ]
        },
        {
            "x": 1,
            "y": 5,
            "z": 5,
            "elements": [
                "immersiveengineering:sheetmetal@1"
            ]
        },
        {
            "x": -2,
            "y": -1,
            "z": 2,
            "elements": [
                "immersiveengineering:sheetmetal@1"
            ]
        },
        {
            "x": 2,
            "y": 5,
            "z": 5,
            "elements": [
                "immersiveengineering:sheetmetal@1"
            ]
        },
        {
            "x": -1,
            "y": -1,
            "z": 2,
            "elements": [
                "immersiveengineering:sheetmetal@1"
            ]
        },
        {
            "x": 0,
            "y": -1,
            "z": 2,
            "elements": [
                "immersiveengineering:sheetmetal@1"
            ]
        },
        {
            "x": 3,
            "y": 3,
            "z": 4,
            "elements": [
                "immersiveengineering:sheetmetal@1"
            ]
        },
        {
            "x": 1,
            "y": -1,
            "z": 2,
            "elements": [
                "immersiveengineering:sheetmetal@1"
            ]
        },
        {
            "x": 3,
            "y": 1,
            "z": 3,
            "elements": [
                "immersiveengineering:sheetmetal@1"
            ]
        },
        {
            "x": 2,
            "y": -1,
            "z": 2,
            "elements": [
                "immersiveengineering:sheetmetal@1"
            ]
        },
        {
            "x": -2,
            "y": 20,
            "z": 4,
            "elements": [
                "immersiveengineering:sheetmetal@1"
            ]
        },
        {
            "x": -2,
            "y": 18,
            "z": 3,
            "elements": [
                "immersiveengineering:sheetmetal@1"
            ]
        },
        {
            "x": -1,
            "y": 20,
            "z": 4,
            "elements": [
                "immersiveengineering:sheetmetal@1"
            ]
        },
        {
            "x": -2,
            "y": 16,
            "z": 2,
            "elements": [
                "immersiveengineering:sheetmetal@1"
            ]
        },
        {
            "x": -1,
            "y": 18,
            "z": 3,
            "elements": [
                "contenttweaker:separatorinternal@0"
            ]
        },
        {
            "x": 1,
            "y": 20,
            "z": 4,
            "elements": [
                "immersiveengineering:sheetmetal@1"
            ]
        },
        {
            "x": 0,
            "y": 18,
            "z": 3,
            "elements": [
                "contenttweaker:separatorinternal@0"
            ]
        },
        {
            "x": -1,
            "y": 14,
            "z": 1,
            "elements": [
                "immersiveengineering:sheetmetal@1"
            ]
        },
        {
            "x": 2,
            "y": 20,
            "z": 4,
            "elements": [
                "immersiveengineering:sheetmetal@1"
            ]
        },
        {
            "x": 1,
            "y": 18,
            "z": 3,
            "elements": [
                "contenttweaker:columninternal@0"
            ]
        },
        {
            "x": 2,
            "y": 18,
            "z": 3,
            "elements": [
                "immersiveengineering:sheetmetal@1"
            ]
        },
        {
            "x": 0,
            "y": 14,
            "z": 1,
            "elements": [
                "immersiveengineering:sheetmetal@1"
            ]
        },
        {
            "x": 2,
            "y": 16,
            "z": 2,
            "elements": [
                "immersiveengineering:sheetmetal@1"
            ]
        },
        {
            "x": 1,
            "y": 14,
            "z": 1,
            "elements": [
                "immersiveengineering:sheetmetal@1"
            ]
        },
        {
            "x": -3,
            "y": 4,
            "z": 4,
            "elements": [
                "immersiveengineering:sheetmetal@1"
            ]
        },
        {
            "x": -3,
            "y": 2,
            "z": 3,
            "elements": [
                "immersiveengineering:sheetmetal@1"
            ]
        },
        {
            "x": -1,
            "y": 6,
            "z": 5,
            "elements": [
                "immersiveengineering:sheetmetal@1"
            ]
        },
        {
            "x": 0,
            "y": 6,
            "z": 5,
            "elements": [
                "immersiveengineering:sheetmetal@1"
            ]
        },
        {
            "x": -3,
            "y": 0,
            "z": 2,
            "elements": [
                "immersiveengineering:sheetmetal@1"
            ]
        },
        {
            "x": 1,
            "y": 6,
            "z": 5,
            "elements": [
                "immersiveengineering:sheetmetal@1"
            ]
        },
        {
            "x": -2,
            "y": 0,
            "z": 2,
            "elements": [
                "immersiveengineering:sheetmetal@1"
            ]
        },
        {
            "x": 3,
            "y": 4,
            "z": 4,
            "elements": [
                "immersiveengineering:sheetmetal@1"
            ]
        },
        {
            "x": 3,
            "y": 2,
            "z": 3,
            "elements": [
                "immersiveengineering:sheetmetal@1"
            ]
        },
        {
            "x": 2,
            "y": 0,
            "z": 2,
            "elements": [
                "immersiveengineering:sheetmetal@1"
            ]
        },
        {
            "x": 3,
            "y": 0,
            "z": 2,
            "elements": [
                "immersiveengineering:sheetmetal@1"
            ]
        },
        {
            "x": -2,
            "y": 19,
            "z": 3,
            "elements": [
                "immersiveengineering:sheetmetal@1"
            ]
        },
        {
            "x": -1,
            "y": 21,
            "z": 4,
            "elements": [
                "immersiveengineering:sheetmetal@1"
            ]
        },
        {
            "x": 0,
            "y": 21,
            "z": 4,
            "elements": [
                "immersiveengineering:sheetmetal@1"
            ]
        },
        {
            "x": -2,
            "y": 17,
            "z": 2,
            "elements": [
                "immersiveengineering:sheetmetal@1"
            ]
        },
        {
            "x": 1,
            "y": 21,
            "z": 4,
            "elements": [
                "immersiveengineering:sheetmetal@1"
            ]
        },
        {
            "x": -1,
            "y": 15,
            "z": 1,
            "elements": [
                "immersiveengineering:sheetmetal@1"
            ]
        },
        {
            "x": 2,
            "y": 19,
            "z": 3,
            "elements": [
                "immersiveengineering:sheetmetal@1"
            ]
        },
        {
            "x": 0,
            "y": 15,
            "z": 1,
            "elements": [
                "immersiveengineering:sheetmetal@1"
            ]
        },
        {
            "x": 2,
            "y": 17,
            "z": 2,
            "elements": [
                "immersiveengineering:sheetmetal@1"
            ]
        },
        {
            "x": 1,
            "y": 15,
            "z": 1,
            "elements": [
                "immersiveengineering:sheetmetal@1"
            ]
        },
        {
            "x": -3,
            "y": 5,
            "z": 4,
            "elements": [
                "immersiveengineering:sheetmetal@1"
            ]
        },
        {
            "x": -3,
            "y": 3,
            "z": 3,
            "elements": [
                "immersiveengineering:sheetmetal@1"
            ]
        },
        {
            "x": -2,
            "y": 5,
            "z": 4,
            "elements": [
                "immersiveengineering:sheetmetal@1"
            ]
        },
        {
            "x": -1,
            "y": 7,
            "z": 5,
            "elements": [
                "immersiveengineering:sheetmetal@1"
            ]
        },
        {
            "x": 0,
            "y": 7,
            "z": 5,
            "elements": [
                "immersiveengineering:sheetmetal@1"
            ]
        },
        {
            "x": -3,
            "y": 1,
            "z": 2,
            "elements": [
                "immersiveengineering:sheetmetal@1"
            ]
        },
        {
            "x": 1,
            "y": 7,
            "z": 5,
            "elements": [
                "immersiveengineering:sheetmetal@1"
            ]
        },
        {
            "x": 2,
            "y": 5,
            "z": 4,
            "elements": [
                "immersiveengineering:sheetmetal@1"
            ]
        },
        {
            "x": -1,
            "y": -1,
            "z": 1,
            "elements": [
                "immersiveengineering:sheetmetal@1"
            ]
        },
        {
            "x": 0,
            "y": -1,
            "z": 1,
            "elements": [
                "immersiveengineering:sheetmetal@1"
            ]
        },
        {
            "x": 3,
            "y": 5,
            "z": 4,
            "elements": [
                "immersiveengineering:sheetmetal@1"
            ]
        },
        {
            "x": 3,
            "y": 3,
            "z": 3,
            "elements": [
                "immersiveengineering:sheetmetal@1"
            ]
        },
        {
            "x": 1,
            "y": -1,
            "z": 1,
            "elements": [
                "immersiveengineering:sheetmetal@1"
            ]
        },
        {
            "x": 3,
            "y": 1,
            "z": 2,
            "elements": [
                "immersiveengineering:sheetmetal@1"
            ]
        },
        {
            "x": -2,
            "y": 20,
            "z": 3,
            "elements": [
                "immersiveengineering:sheetmetal@1"
            ]
        },
        {
            "x": -2,
            "y": 18,
            "z": 2,
            "elements": [
                "immersiveengineering:sheetmetal@1"
            ]
        },
        {
            "x": -1,
            "y": 18,
            "z": 2,
            "elements": [
                "contenttweaker:separatorinternal@0"
            ]
        },
        {
            "x": 0,
            "y": 18,
            "z": 2,
            "elements": [
                "contenttweaker:separatorinternal@0"
            ]
        },
        {
            "x": -1,
            "y": 16,
            "z": 1,
            "elements": [
                "immersiveengineering:sheetmetal@1"
            ]
        },
        {
            "x": 2,
            "y": 20,
            "z": 3,
            "elements": [
                "immersiveengineering:sheetmetal@1"
            ]
        },
        {
            "x": 1,
            "y": 18,
            "z": 2,
            "elements": [
                "contenttweaker:separatorinternal@0"
            ]
        },
        {
            "x": 0,
            "y": 16,
            "z": 1,
            "elements": [
                "immersiveengineering:sheetmetal@1"
            ]
        },
        {
            "x": 2,
            "y": 18,
            "z": 2,
            "elements": [
                "immersiveengineering:sheetmetal@1"
            ]
        },
        {
            "x": 1,
            "y": 16,
            "z": 1,
            "elements": [
                "immersiveengineering:sheetmetal@1"
            ]
        },
        {
            "x": -3,
            "y": 4,
            "z": 3,
            "elements": [
                "immersiveengineering:sheetmetal@1"
            ]
        },
        {
            "x": -2,
            "y": 6,
            "z": 4,
            "elements": [
                "immersiveengineering:sheetmetal@1"
            ]
        },
        {
            "x": -1,
            "y": 8,
            "z": 5,
            "elements": [
                "immersiveengineering:sheetmetal@1"
            ]
        },
        {
            "x": 0,
            "y": 8,
            "z": 5,
            "elements": [
                "immersiveengineering:sheetmetal@1"
            ]
        },
        {
            "x": -3,
            "y": 2,
            "z": 2,
            "elements": [
                "immersiveengineering:sheetmetal@1"
            ]
        },
        {
            "x": 1,
            "y": 8,
            "z": 5,
            "elements": [
                "immersiveengineering:sheetmetal@1"
            ]
        },
        {
            "x": -2,
            "y": 0,
            "z": 1,
            "elements": [
                "immersiveengineering:sheetmetal@1"
            ]
        },
        {
            "x": 2,
            "y": 6,
            "z": 4,
            "elements": [
                "immersiveengineering:sheetmetal@1"
            ]
        },
        {
            "x": -1,
            "y": 0,
            "z": 1,
            "elements": [
                "immersiveengineering:sheetmetal@1"
            ]
        },
        {
            "x": 0,
            "y": 0,
            "z": 1,
            "elements": [
                "immersiveengineering:sheetmetal@1"
            ]
        },
        {
            "x": 3,
            "y": 4,
            "z": 3,
            "elements": [
                "immersiveengineering:sheetmetal@1"
            ]
        },
        {
            "x": 1,
            "y": 0,
            "z": 1,
            "elements": [
                "immersiveengineering:sheetmetal@1"
            ]
        },
        {
            "x": 3,
            "y": 2,
            "z": 2,
            "elements": [
                "immersiveengineering:sheetmetal@1"
            ]
        },
        {
            "x": 2,
            "y": 0,
            "z": 1,
            "elements": [
                "immersiveengineering:sheetmetal@1"
            ]
        },
        {
            "x": -2,
            "y": 19,
            "z": 2,
            "elements": [
                "immersiveengineering:sheetmetal@1"
            ]
        },
        {
            "x": -1,
            "y": 21,
            "z": 3,
            "elements": [
                "immersiveengineering:sheetmetal@1"
            ]
        },
        {
            "x": 0,
            "y": 21,
            "z": 3,
            "elements": [
                "modularmachinery:blockfluidoutputhatch"
            ]
        },
        {
            "x": 1,
            "y": 21,
            "z": 3,
            "elements": [
                "immersiveengineering:sheetmetal@1"
            ]
        },
        {
            "x": -1,
            "y": 17,
            "z": 1,
            "elements": [
                "immersiveengineering:sheetmetal@1"
            ]
        },
        {
            "x": 0,
            "y": 17,
            "z": 1,
            "elements": [
                "immersiveengineering:sheetmetal@1"
            ]
        },
        {
            "x": 2,
            "y": 19,
            "z": 2,
            "elements": [
                "immersiveengineering:sheetmetal@1"
            ]
        },
        {
            "x": 1,
            "y": 17,
            "z": 1,
            "elements": [
                "immersiveengineering:sheetmetal@1"
            ]
        },
        {
            "x": -3,
            "y": 5,
            "z": 3,
            "elements": [
                "immersiveengineering:sheetmetal@1"
            ]
        },
        {
            "x": -2,
            "y": 7,
            "z": 4,
            "elements": [
                "immersiveengineering:sheetmetal@1"
            ]
        },
        {
            "x": -1,
            "y": 9,
            "z": 5,
            "elements": [
                "immersiveengineering:sheetmetal@1"
            ]
        },
        {
            "x": -3,
            "y": 3,
            "z": 2,
            "elements": [
                "immersiveengineering:sheetmetal@1"
            ]
        },
        {
            "x": -2,
            "y": 5,
            "z": 3,
            "elements": [
                "immersiveengineering:sheetmetal@1"
            ]
        },
        {
            "x": 0,
            "y": 9,
            "z": 5,
            "elements": [
                "immersiveengineering:sheetmetal@1"
            ]
        },
        {
            "x": 1,
            "y": 9,
            "z": 5,
            "elements": [
                "immersiveengineering:sheetmetal@1"
            ]
        },
        {
            "x": -1,
            "y": 5,
            "z": 3,
            "elements": [
                "contenttweaker:columninternal@0"
            ]
        },
        {
            "x": 0,
            "y": 5,
            "z": 3,
            "elements": [
                "contenttweaker:columninternal@0"
            ]
        },
        {
            "x": -2,
            "y": 1,
            "z": 1,
            "elements": [
                "immersiveengineering:sheetmetal@1"
            ]
        },
        {
            "x": 2,
            "y": 7,
            "z": 4,
            "elements": [
                "immersiveengineering:sheetmetal@1"
            ]
        },
        {
            "x": 1,
            "y": 5,
            "z": 3,
            "elements": [
                "contenttweaker:columninternal@0"
            ]
        },
        {
            "x": 2,
            "y": 5,
            "z": 3,
            "elements": [
                "immersiveengineering:sheetmetal@1"
            ]
        },
        {
            "x": 3,
            "y": 5,
            "z": 3,
            "elements": [
                "immersiveengineering:sheetmetal@1"
            ]
        },
        {
            "x": 3,
            "y": 3,
            "z": 2,
            "elements": [
                "immersiveengineering:sheetmetal@1"
            ]
        },
        {
            "x": 2,
            "y": 1,
            "z": 1,
            "elements": [
                "immersiveengineering:sheetmetal@1"
            ]
        },
        {
            "x": -2,
            "y": 20,
            "z": 2,
            "elements": [
                "immersiveengineering:sheetmetal@1"
            ]
        },
        {
            "x": -1,
            "y": 20,
            "z": 2,
            "elements": [
                "immersiveengineering:sheetmetal@1"
            ]
        },
        {
            "x": -1,
            "y": 18,
            "z": 1,
            "elements": [
                "immersiveengineering:sheetmetal@1"
            ]
        },
        {
            "x": 1,
            "y": 20,
            "z": 2,
            "elements": [
                "immersiveengineering:sheetmetal@1"
            ]
        },
        {
            "x": 0,
            "y": 18,
            "z": 1,
            "elements": [
                "immersiveengineering:sheetmetal@1"
            ]
        },
        {
            "x": 2,
            "y": 20,
            "z": 2,
            "elements": [
                "immersiveengineering:sheetmetal@1"
            ]
        },
        {
            "x": 1,
            "y": 18,
            "z": 1,
            "elements": [
                "immersiveengineering:sheetmetal@1"
            ]
        },
        {
            "x": -2,
            "y": 8,
            "z": 4,
            "elements": [
                "immersiveengineering:sheetmetal@1"
            ]
        },
        {
            "x": -1,
            "y": 10,
            "z": 5,
            "elements": [
                "immersiveengineering:sheetmetal@1"
            ]
        },
        {
            "x": -3,
            "y": 4,
            "z": 2,
            "elements": [
                "immersiveengineering:sheetmetal@1"
            ]
        },
        {
            "x": -2,
            "y": 6,
            "z": 3,
            "elements": [
                "immersiveengineering:sheetmetal@1"
            ]
        },
        {
            "x": 0,
            "y": 10,
            "z": 5,
            "elements": [
                "immersiveengineering:sheetmetal@1"
            ]
        },
        {
            "x": 1,
            "y": 10,
            "z": 5,
            "elements": [
                "immersiveengineering:sheetmetal@1"
            ]
        },
        {
            "x": -2,
            "y": 2,
            "z": 1,
            "elements": [
                "immersiveengineering:sheetmetal@1"
            ]
        },
        {
            "x": 2,
            "y": 8,
            "z": 4,
            "elements": [
                "immersiveengineering:sheetmetal@1"
            ]
        },
        {
            "x": 2,
            "y": 6,
            "z": 3,
            "elements": [
                "immersiveengineering:sheetmetal@1"
            ]
        }
    ]}
