{
    "registryname": "reactoradvsmall",
    "localizedname": "Advanced Fixed Bed Reactor (Small)",
    "color": "F3FAFF",
    "parts": [
        {
            "x": -1,
            "y": 0,
            "z": 0,
            "elements": [
                "immersiveengineering:sheetmetal@1"
            ]
        },
        {
            "x": 1,
            "y": 2,
            "z": 1,
            "elements": [
                "immersiveengineering:sheetmetal@1"
            ]
        },
        {
            "x": 1,
            "y": 0,
            "z": 0,
            "elements": [
                "immersiveengineering:sheetmetal@1"
            ]
        },
        {
            "x": -1,
            "y": 0,
            "z": 2,
            "elements": [
                "immersiveengineering:sheetmetal@1"
            ]
        },
        {
            "x": 0,
            "y": 0,
            "z": 2,
            "elements": [
                "modularmachinery:blockredstonebus@0"
            ]
        },
        {
            "x": 1,
            "y": 0,
            "z": 2,
            "elements": [
                "immersiveengineering:sheetmetal@1"
            ]
        },
        {
            "x": 0,
            "y": 9,
            "z": 0,
            "elements": [
                "immersiveengineering:sheetmetal@1"
            ]
        },
        {
            "x": 0,
            "y": 9,
            "z": 2,
            "elements": [
                "immersiveengineering:sheetmetal@1"
            ]
        },
        {
            "x": -1,
            "y": 7,
            "z": 1,
            "elements": [
                "immersiveengineering:sheetmetal@1"
            ]
        },
        {
            "x": -1,
            "y": 5,
            "z": 0,
            "elements": [
                "immersiveengineering:sheetmetal@1"
            ]
        },
        {
            "x": 0,
            "y": 7,
            "z": 1,
            "elements": [
                "casings_catalyst"
            ]
        },
        {
            "x": 1,
            "y": 7,
            "z": 1,
            "elements": [
                "immersiveengineering:sheetmetal@1"
            ]
        },
        {
            "x": 0,
            "y": 5,
            "z": 0,
            "elements": [
                "immersiveengineering:sheetmetal@1"
            ]
        },
        {
            "x": -1,
            "y": 5,
            "z": 2,
            "elements": [
                "immersiveengineering:sheetmetal@1"
            ]
        },
        {
            "x": 1,
            "y": 5,
            "z": 0,
            "elements": [
                "immersiveengineering:sheetmetal@1"
            ]
        },
        {
            "x": 0,
            "y": 5,
            "z": 2,
            "elements": [
                "immersiveengineering:sheetmetal@1"
            ]
        },
        {
            "x": -1,
            "y": 3,
            "z": 1,
            "elements": [
                "immersiveengineering:sheetmetal@1"
            ]
        },
        {
            "x": 0,
            "y": -1,
            "z": 0,
            "elements": [
                "immersiveengineering:sheetmetal@1"
            ]
        },
        {
            "x": -1,
            "y": 1,
            "z": 0,
            "elements": [
                "immersiveengineering:sheetmetal@1"
            ]
        },
        {
            "x": 1,
            "y": 5,
            "z": 2,
            "elements": [
                "immersiveengineering:sheetmetal@1"
            ]
        },
        {
            "x": 0,
            "y": 3,
            "z": 1,
            "elements": [
                "contenttweaker:reactorinternal@0"
            ]
        },
        {
            "x": 1,
            "y": 3,
            "z": 1,
            "elements": [
                "immersiveengineering:sheetmetal@1"
            ]
        },
        {
            "x": 0,
            "y": 1,
            "z": 0,
            "elements": [
                "immersiveengineering:sheetmetal@1"
            ]
        },
        {
            "x": -1,
            "y": 1,
            "z": 2,
            "elements": [
                "immersiveengineering:sheetmetal@1"
            ]
        },
        {
            "x": 1,
            "y": 1,
            "z": 0,
            "elements": [
                "immersiveengineering:sheetmetal@1"
            ]
        },
        {
            "x": 0,
            "y": 1,
            "z": 2,
            "elements": [
                "immersiveengineering:sheetmetal@1"
            ]
        },
        {
            "x": -1,
            "y": -1,
            "z": 1,
            "elements": [
                "immersiveengineering:sheetmetal@1"
            ]
        },
        {
            "x": 0,
            "y": -1,
            "z": 1,
            "elements": [
                "modularmachinery:blockfluidoutputhatch"
            ]
        },
        {
            "x": 1,
            "y": 1,
            "z": 2,
            "elements": [
                "immersiveengineering:sheetmetal@1"
            ]
        },
        {
            "x": 1,
            "y": -1,
            "z": 1,
            "elements": [
                "immersiveengineering:sheetmetal@1"
            ]
        },
        {
            "x": -1,
            "y": 8,
            "z": 1,
            "elements": [
                "immersiveengineering:sheetmetal@1"
            ]
        },
        {
            "x": -1,
            "y": 6,
            "z": 0,
            "elements": [
                "immersiveengineering:sheetmetal@1"
            ]
        },
        {
            "x": 0,
            "y": 8,
            "z": 1,
            "elements": [
                "contenttweaker:reactorinternal@0"
            ]
        },
        {
            "x": 1,
            "y": 8,
            "z": 1,
            "elements": [
                "immersiveengineering:sheetmetal@1"
            ]
        },
        {
            "x": 0,
            "y": 6,
            "z": 0,
            "elements": [
                "immersiveengineering:sheetmetal@1"
            ]
        },
        {
            "x": -1,
            "y": 6,
            "z": 2,
            "elements": [
                "immersiveengineering:sheetmetal@1"
            ]
        },
        {
            "x": 1,
            "y": 6,
            "z": 0,
            "elements": [
                "immersiveengineering:sheetmetal@1"
            ]
        },
        {
            "x": 0,
            "y": 6,
            "z": 2,
            "elements": [
                "immersiveengineering:sheetmetal@1"
            ]
        },
        {
            "x": -1,
            "y": 4,
            "z": 1,
            "elements": [
                "immersiveengineering:sheetmetal@1"
            ]
        },
        {
            "x": -1,
            "y": 2,
            "z": 0,
            "elements": [
                "immersiveengineering:sheetmetal@1"
            ]
        },
        {
            "x": 1,
            "y": 6,
            "z": 2,
            "elements": [
                "immersiveengineering:sheetmetal@1"
            ]
        },
        {
            "x": 0,
            "y": 4,
            "z": 1,
            "elements": [
                "contenttweaker:advreactorinternal@0"
            ]
        },
        {
            "x": 1,
            "y": 4,
            "z": 1,
            "elements": [
                "immersiveengineering:sheetmetal@1"
            ]
        },
        {
            "x": 0,
            "y": 2,
            "z": 0,
            "elements": [
                "immersiveengineering:sheetmetal@1"
            ]
        },
        {
            "x": -1,
            "y": 2,
            "z": 2,
            "elements": [
                "immersiveengineering:sheetmetal@1"
            ]
        },
        {
            "x": 1,
            "y": 2,
            "z": 0,
            "elements": [
                "immersiveengineering:sheetmetal@1"
            ]
        },
        {
            "x": 0,
            "y": 2,
            "z": 2,
            "elements": [
                "immersiveengineering:sheetmetal@1"
            ]
        },
        {
            "x": -1,
            "y": 0,
            "z": 1,
            "elements": [
                "immersiveengineering:sheetmetal@1"
            ]
        },
        {
            "x": 0,
            "y": 0,
            "z": 1,
            "elements": [
                "contenttweaker:reactorinternal@0"
            ]
        },
        {
            "x": 1,
            "y": 2,
            "z": 2,
            "elements": [
                "immersiveengineering:sheetmetal@1"
            ]
        },
        {
            "x": 1,
            "y": 0,
            "z": 1,
            "elements": [
                "immersiveengineering:sheetmetal@1"
            ]
        },
        {
            "x": -1,
            "y": 9,
            "z": 1,
            "elements": [
                "immersiveengineering:sheetmetal@1"
            ]
        },
        {
            "x": 0,
            "y": 9,
            "z": 1,
            "elements": [
                "modularmachinery:blockfluidinputhatch"
            ]
        },
        {
            "x": -1,
            "y": 7,
            "z": 0,
            "elements": [
                "immersiveengineering:sheetmetal@1"
            ]
        },
        {
            "x": 1,
            "y": 9,
            "z": 1,
            "elements": [
                "immersiveengineering:sheetmetal@1"
            ]
        },
        {
            "x": 0,
            "y": 7,
            "z": 0,
            "elements": [
                "immersiveengineering:sheetmetal@1"
            ]
        },
        {
            "x": 1,
            "y": 7,
            "z": 0,
            "elements": [
                "immersiveengineering:sheetmetal@1"
            ]
        },
        {
            "x": -1,
            "y": 7,
            "z": 2,
            "elements": [
                "immersiveengineering:sheetmetal@1"
            ]
        },
        {
            "x": -1,
            "y": 5,
            "z": 1,
            "elements": [
                "immersiveengineering:sheetmetal@1"
            ]
        },
        {
            "x": 0,
            "y": 7,
            "z": 2,
            "elements": [
                "immersiveengineering:sheetmetal@1"
            ]
        },
        {
            "x": 1,
            "y": 7,
            "z": 2,
            "elements": [
                "immersiveengineering:sheetmetal@1"
            ]
        },
        {
            "x": 0,
            "y": 5,
            "z": 1,
            "elements": [
                "contenttweaker:reactorinternal@0"
            ]
        },
        {
            "x": -1,
            "y": 3,
            "z": 0,
            "elements": [
                "immersiveengineering:sheetmetal@1"
            ]
        },
        {
            "x": 1,
            "y": 5,
            "z": 1,
            "elements": [
                "immersiveengineering:sheetmetal@1"
            ]
        },
        {
            "x": 0,
            "y": 3,
            "z": 0,
            "elements": [
                "immersiveengineering:sheetmetal@1"
            ]
        },
        {
            "x": 1,
            "y": 3,
            "z": 0,
            "elements": [
                "immersiveengineering:sheetmetal@1"
            ]
        },
        {
            "x": -1,
            "y": 3,
            "z": 2,
            "elements": [
                "immersiveengineering:sheetmetal@1"
            ]
        },
        {
            "x": -1,
            "y": 1,
            "z": 1,
            "elements": [
                "immersiveengineering:sheetmetal@1"
            ]
        },
        {
            "x": 0,
            "y": 3,
            "z": 2,
            "elements": [
                "immersiveengineering:sheetmetal@1"
            ]
        },
        {
            "x": 1,
            "y": 3,
            "z": 2,
            "elements": [
                "immersiveengineering:sheetmetal@1"
            ]
        },
        {
            "x": 0,
            "y": 1,
            "z": 1,
            "elements": [
                "casings_catalyst"
            ]
        },
        {
            "x": 1,
            "y": 1,
            "z": 1,
            "elements": [
                "immersiveengineering:sheetmetal@1"
            ]
        },
        {
            "x": 0,
            "y": -1,
            "z": 2,
            "elements": [
                "immersiveengineering:sheetmetal@1"
            ]
        },
        {
            "x": -1,
            "y": 8,
            "z": 0,
            "elements": [
                "immersiveengineering:sheetmetal@1"
            ]
        },
        {
            "x": 0,
            "y": 8,
            "z": 0,
            "elements": [
                "immersiveengineering:sheetmetal@1"
            ]
        },
        {
            "x": 1,
            "y": 8,
            "z": 0,
            "elements": [
                "immersiveengineering:sheetmetal@1"
            ]
        },
        {
            "x": -1,
            "y": 8,
            "z": 2,
            "elements": [
                "immersiveengineering:sheetmetal@1"
            ]
        },
        {
            "x": -1,
            "y": 6,
            "z": 1,
            "elements": [
                "immersiveengineering:sheetmetal@1"
            ]
        },
        {
            "x": 0,
            "y": 8,
            "z": 2,
            "elements": [
                "immersiveengineering:sheetmetal@1"
            ]
        },
        {
            "x": 1,
            "y": 8,
            "z": 2,
            "elements": [
                "immersiveengineering:sheetmetal@1"
            ]
        },
        {
            "x": 0,
            "y": 6,
            "z": 1,
            "elements": [
                "casings_catalyst"
            ]
        },
        {
            "x": -1,
            "y": 4,
            "z": 0,
            "elements": [
                "immersiveengineering:sheetmetal@1"
            ]
        },
        {
            "x": 1,
            "y": 6,
            "z": 1,
            "elements": [
                "immersiveengineering:sheetmetal@1"
            ]
        },
        {
            "x": 0,
            "y": 4,
            "z": 0,
            "elements": [
                "modularmachinery:blockfluidinputhatch"
            ]
        },
        {
            "x": 1,
            "y": 4,
            "z": 0,
            "elements": [
                "immersiveengineering:sheetmetal@1"
            ]
        },
        {
            "x": -1,
            "y": 4,
            "z": 2,
            "elements": [
                "immersiveengineering:sheetmetal@1"
            ]
        },
        {
            "x": -1,
            "y": 2,
            "z": 1,
            "elements": [
                "immersiveengineering:sheetmetal@1"
            ]
        },
        {
            "x": 0,
            "y": 4,
            "z": 2,
            "elements": [
                "modularmachinery:blockfluidoutputhatch"
            ]
        },
        {
            "x": 1,
            "y": 4,
            "z": 2,
            "elements": [
                "immersiveengineering:sheetmetal@1"
            ]
        },
        {
            "x": 0,
            "y": 2,
            "z": 1,
            "elements": [
                "casings_catalyst"
            ]
        }
    ]}