{
    "registryname": "reactormedium",
    "localizedname": "Fixed Bed Reactor (Medium)",
    "color": "AEAEAE",
    "parts": [
        {
            "x": -2,
            "y": -2,
            "z": -1,
            "elements": [
                "industrialrenewal:catwalk_steel_pillar@0"
            ]
        },
        {
            "x": -1,
            "y": 0,
            "z": 0,
            "elements": [
                "industrialrenewal:catwalk_column_steel@0"
            ]
        },
        {
            "x": 1,
            "y": 2,
            "z": 1,
            "elements": [
                "contenttweaker:reactorinternal@0"
            ]
        },
        {
            "x": -2,
            "y": 0,
            "z": 0,
            "elements": [
                "industrialrenewal:catwalk_column_steel@0"
            ]
        },
        {
            "x": 2,
            "y": 2,
            "z": 1,
            "elements": [
                "contenttweaker:steelcasing@0"
            ]
        },
        {
            "x": 1,
            "y": 0,
            "z": 0,
            "elements": [
                "industrialrenewal:catwalk_column_steel@0"
            ]
        },
        {
            "x": 2,
            "y": 0,
            "z": 0,
            "elements": [
                "industrialrenewal:catwalk_column_steel@0"
            ]
        },
        {
            "x": -2,
            "y": -2,
            "z": 3,
            "elements": [
                "industrialrenewal:catwalk_steel_pillar@0"
            ]
        },
        {
            "x": 0,
            "y": 6,
            "z": -1,
            "elements": [
                "contenttweaker:steelcasing@0"
            ]
        },
        {
            "x": 2,
            "y": -2,
            "z": 3,
            "elements": [
                "industrialrenewal:catwalk_steel_pillar@0"
            ]
        },
        {
            "x": 0,
            "y": 14,
            "z": -1,
            "elements": [
                "contenttweaker:steelcasing@0"
            ]
        },
        {
            "x": -2,
            "y": 11,
            "z": 1,
            "elements": [
                "contenttweaker:steelcasing@0"
            ]
        },
        {
            "x": -1,
            "y": 13,
            "z": 2,
            "elements": [
                "contenttweaker:steelcasing@0"
            ]
        },
        {
            "x": 0,
            "y": 15,
            "z": 3,
            "elements": [
                "contenttweaker:steelcasing@0"
            ]
        },
        {
            "x": 1,
            "y": 13,
            "z": 2,
            "elements": [
                "contenttweaker:steelcasing@0"
            ]
        },
        {
            "x": -1,
            "y": 9,
            "z": 0,
            "elements": [
                "contenttweaker:steelcasing@0"
            ]
        },
        {
            "x": 2,
            "y": 11,
            "z": 1,
            "elements": [
                "contenttweaker:steelcasing@0"
            ]
        },
        {
            "x": 1,
            "y": 9,
            "z": 0,
            "elements": [
                "contenttweaker:steelcasing@0"
            ]
        },
        {
            "x": -2,
            "y": 3,
            "z": 1,
            "elements": [
                "contenttweaker:steelcasing@0"
            ]
        },
        {
            "x": -1,
            "y": 5,
            "z": 2,
            "elements": [
                "contenttweaker:steelcasing@0"
            ]
        },
        {
            "x": 0,
            "y": 7,
            "z": 3,
            "elements": [
                "contenttweaker:steelcasing@0"
            ]
        },
        {
            "x": 1,
            "y": 5,
            "z": 2,
            "elements": [
                "contenttweaker:steelcasing@0"
            ]
        },
        {
            "x": -1,
            "y": 1,
            "z": 0,
            "elements": [
                "contenttweaker:steelcasing@0"
            ]
        },
        {
            "x": 0,
            "y": 1,
            "z": 0,
            "elements": [
                "contenttweaker:steelcasing@0"
            ]
        },
        {
            "x": 2,
            "y": 3,
            "z": 1,
            "elements": [
                "contenttweaker:steelcasing@0"
            ]
        },
        {
            "x": 1,
            "y": 1,
            "z": 0,
            "elements": [
                "contenttweaker:steelcasing@0"
            ]
        },
        {
            "x": -2,
            "y": -1,
            "z": 3,
            "elements": [
                "industrialrenewal:catwalk_steel_pillar@0"
            ]
        },
        {
            "x": 0,
            "y": 5,
            "z": -1,
            "elements": [
                "contenttweaker:steelcasing@0"
            ]
        },
        {
            "x": 2,
            "y": -1,
            "z": 3,
            "elements": [
                "industrialrenewal:catwalk_steel_pillar@0"
            ]
        },
        {
            "x": 0,
            "y": 13,
            "z": -1,
            "elements": [
                "contenttweaker:steelcasing@0"
            ]
        },
        {
            "x": -2,
            "y": 12,
            "z": 1,
            "elements": [
                "contenttweaker:steelcasing@0"
            ]
        },
        {
            "x": -1,
            "y": 14,
            "z": 2,
            "elements": [
                "contenttweaker:steelcasing@0"
            ]
        },
        {
            "x": 0,
            "y": 14,
            "z": 2,
            "elements": [
                "contenttweaker:reactorinternal@0"
            ]
        },
        {
            "x": 1,
            "y": 14,
            "z": 2,
            "elements": [
                "contenttweaker:steelcasing@0"
            ]
        },
        {
            "x": -1,
            "y": 10,
            "z": 0,
            "elements": [
                "contenttweaker:steelcasing@0"
            ]
        },
        {
            "x": 2,
            "y": 12,
            "z": 1,
            "elements": [
                "contenttweaker:steelcasing@0"
            ]
        },
        {
            "x": 1,
            "y": 10,
            "z": 0,
            "elements": [
                "contenttweaker:steelcasing@0"
            ]
        },
        {
            "x": -2,
            "y": 4,
            "z": 1,
            "elements": [
                "contenttweaker:steelcasing@0"
            ]
        },
        {
            "x": -1,
            "y": 6,
            "z": 2,
            "elements": [
                "contenttweaker:steelcasing@0"
            ]
        },
        {
            "x": 0,
            "y": 8,
            "z": 3,
            "elements": [
                "contenttweaker:steelcasing@0"
            ]
        },
        {
            "x": 1,
            "y": 6,
            "z": 2,
            "elements": [
                "contenttweaker:steelcasing@0"
            ]
        },
        {
            "x": -1,
            "y": 2,
            "z": 0,
            "elements": [
                "contenttweaker:steelcasing@0"
            ]
        },
        {
            "x": 0,
            "y": 2,
            "z": 0,
            "elements": [
                "contenttweaker:reactorinternal@0"
            ]
        },
        {
            "x": 2,
            "y": 4,
            "z": 1,
            "elements": [
                "contenttweaker:steelcasing@0"
            ]
        },
        {
            "x": 1,
            "y": 2,
            "z": 0,
            "elements": [
                "contenttweaker:steelcasing@0"
            ]
        },
        {
            "x": -2,
            "y": 0,
            "z": 3,
            "elements": [
                "industrialrenewal:catwalk_steel_pillar@0"
            ]
        },
        {
            "x": -1,
            "y": 0,
            "z": 3,
            "elements": [
                "industrialrenewal:catwalk_column_steel@0"
            ]
        },
        {
            "x": 0,
            "y": 0,
            "z": 3,
            "elements": [
                "industrialrenewal:catwalk_column_steel@0"
            ]
        },
        {
            "x": 0,
            "y": 4,
            "z": -1,
            "elements": [
                "contenttweaker:steelcasing@0"
            ]
        },
        {
            "x": 1,
            "y": 0,
            "z": 3,
            "elements": [
                "industrialrenewal:catwalk_column_steel@0"
            ]
        },
        {
            "x": 2,
            "y": 0,
            "z": 3,
            "elements": [
                "industrialrenewal:catwalk_steel_pillar@0"
            ]
        },
        {
            "x": 0,
            "y": 12,
            "z": -1,
            "elements": [
                "contenttweaker:steelcasing@0"
            ]
        },
        {
            "x": -2,
            "y": 13,
            "z": 1,
            "elements": [
                "contenttweaker:steelcasing@0"
            ]
        },
        {
            "x": -1,
            "y": 15,
            "z": 2,
            "elements": [
                "contenttweaker:steelcasing@0"
            ]
        },
        {
            "x": 0,
            "y": 15,
            "z": 2,
            "elements": [
                "contenttweaker:steelcasing@0"
            ]
        },
        {
            "x": -1,
            "y": 11,
            "z": 0,
            "elements": [
                "contenttweaker:steelcasing@0"
            ]
        },
        {
            "x": 1,
            "y": 15,
            "z": 2,
            "elements": [
                "contenttweaker:steelcasing@0"
            ]
        },
        {
            "x": 2,
            "y": 13,
            "z": 1,
            "elements": [
                "contenttweaker:steelcasing@0"
            ]
        },
        {
            "x": 1,
            "y": 11,
            "z": 0,
            "elements": [
                "contenttweaker:steelcasing@0"
            ]
        },
        {
            "x": 0,
            "y": 9,
            "z": 3,
            "elements": [
                "contenttweaker:steelcasing@0"
            ]
        },
        {
            "x": -2,
            "y": 5,
            "z": 1,
            "elements": [
                "contenttweaker:steelcasing@0"
            ]
        },
        {
            "x": -1,
            "y": 7,
            "z": 2,
            "elements": [
                "contenttweaker:steelcasing@0"
            ]
        },
        {
            "x": -1,
            "y": 3,
            "z": 0,
            "elements": [
                "contenttweaker:steelcasing@0"
            ]
        },
        {
            "x": 1,
            "y": 7,
            "z": 2,
            "elements": [
                "contenttweaker:steelcasing@0"
            ]
        },
        {
            "x": 2,
            "y": 5,
            "z": 1,
            "elements": [
                "contenttweaker:steelcasing@0"
            ]
        },
        {
            "x": 1,
            "y": 3,
            "z": 0,
            "elements": [
                "contenttweaker:steelcasing@0"
            ]
        },
        {
            "x": 0,
            "y": 1,
            "z": 3,
            "elements": [
                "contenttweaker:steelcasing@0"
            ]
        },
        {
            "x": 0,
            "y": 3,
            "z": -1,
            "elements": [
                "contenttweaker:steelcasing@0"
            ]
        },
        {
            "x": 0,
            "y": 11,
            "z": -1,
            "elements": [
                "contenttweaker:steelcasing@0"
            ]
        },
        {
            "x": -2,
            "y": 14,
            "z": 1,
            "elements": [
                "contenttweaker:steelcasing@0"
            ]
        },
        {
            "x": -1,
            "y": 14,
            "z": 1,
            "elements": [
                "contenttweaker:reactorinternal@0"
            ]
        },
        {
            "x": 0,
            "y": 16,
            "z": 2,
            "elements": [
                "contenttweaker:steelcasing@0"
            ]
        },
        {
            "x": -1,
            "y": 12,
            "z": 0,
            "elements": [
                "contenttweaker:steelcasing@0"
            ]
        },
        {
            "x": 0,
            "y": 14,
            "z": 1,
            "elements": [
                "contenttweaker:reactorinternal@0"
            ]
        },
        {
            "x": 1,
            "y": 14,
            "z": 1,
            "elements": [
                "contenttweaker:reactorinternal@0"
            ]
        },
        {
            "x": 2,
            "y": 14,
            "z": 1,
            "elements": [
                "contenttweaker:steelcasing@0"
            ]
        },
        {
            "x": 1,
            "y": 12,
            "z": 0,
            "elements": [
                "contenttweaker:steelcasing@0"
            ]
        },
        {
            "x": 0,
            "y": 10,
            "z": 3,
            "elements": [
                "contenttweaker:steelcasing@0"
            ]
        },
        {
            "x": -2,
            "y": 6,
            "z": 1,
            "elements": [
                "contenttweaker:steelcasing@0"
            ]
        },
        {
            "x": -1,
            "y": 8,
            "z": 2,
            "elements": [
                "contenttweaker:steelcasing@0"
            ]
        },
        {
            "x": -1,
            "y": 4,
            "z": 0,
            "elements": [
                "contenttweaker:steelcasing@0"
            ]
        },
        {
            "x": 1,
            "y": 8,
            "z": 2,
            "elements": [
                "contenttweaker:steelcasing@0"
            ]
        },
        {
            "x": 2,
            "y": 6,
            "z": 1,
            "elements": [
                "contenttweaker:steelcasing@0"
            ]
        },
        {
            "x": 1,
            "y": 4,
            "z": 0,
            "elements": [
                "contenttweaker:steelcasing@0"
            ]
        },
        {
            "x": -2,
            "y": 0,
            "z": 2,
            "elements": [
                "industrialrenewal:catwalk_column_steel@0"
            ]
        },
        {
            "x": 0,
            "y": 2,
            "z": 3,
            "elements": [
                "contenttweaker:steelcasing@0"
            ]
        },
        {
            "x": -1,
            "y": 0,
            "z": 2,
            "elements": [
                "industrialrenewal:catwalk_column_steel@0"
            ]
        },
        {
            "x": 0,
            "y": 0,
            "z": 2,
            "elements": [
                "contenttweaker:steelcasing@0"
            ]
        },
        {
            "x": 0,
            "y": 2,
            "z": -1,
            "elements": [
                "contenttweaker:steelcasing@0"
            ]
        },
        {
            "x": 1,
            "y": 0,
            "z": 2,
            "elements": [
                "industrialrenewal:catwalk_column_steel@0"
            ]
        },
        {
            "x": 2,
            "y": 0,
            "z": 2,
            "elements": [
                "industrialrenewal:catwalk_column_steel@0"
            ]
        },
        {
            "x": 0,
            "y": 10,
            "z": -1,
            "elements": [
                "contenttweaker:steelcasing@0"
            ]
        },
        {
            "x": -2,
            "y": 15,
            "z": 1,
            "elements": [
                "contenttweaker:steelcasing@0"
            ]
        },
        {
            "x": -1,
            "y": 15,
            "z": 1,
            "elements": [
                "contenttweaker:steelcasing@0"
            ]
        },
        {
            "x": -1,
            "y": 13,
            "z": 0,
            "elements": [
                "contenttweaker:steelcasing@0"
            ]
        },
        {
            "x": 1,
            "y": 15,
            "z": 1,
            "elements": [
                "contenttweaker:steelcasing@0"
            ]
        },
        {
            "x": 2,
            "y": 15,
            "z": 1,
            "elements": [
                "contenttweaker:steelcasing@0"
            ]
        },
        {
            "x": 1,
            "y": 13,
            "z": 0,
            "elements": [
                "contenttweaker:steelcasing@0"
            ]
        },
        {
            "x": 0,
            "y": 11,
            "z": 3,
            "elements": [
                "contenttweaker:steelcasing@0"
            ]
        },
        {
            "x": -2,
            "y": 7,
            "z": 1,
            "elements": [
                "contenttweaker:steelcasing@0"
            ]
        },
        {
            "x": -1,
            "y": 9,
            "z": 2,
            "elements": [
                "contenttweaker:steelcasing@0"
            ]
        },
        {
            "x": -1,
            "y": 5,
            "z": 0,
            "elements": [
                "contenttweaker:steelcasing@0"
            ]
        },
        {
            "x": 1,
            "y": 9,
            "z": 2,
            "elements": [
                "contenttweaker:steelcasing@0"
            ]
        },
        {
            "x": 0,
            "y": 7,
            "z": 1,
            "elements": [
                "casings_catalyst"
            ]
        },
        {
            "x": 2,
            "y": 7,
            "z": 1,
            "elements": [
                "contenttweaker:steelcasing@0"
            ]
        },
        {
            "x": 1,
            "y": 5,
            "z": 0,
            "elements": [
                "contenttweaker:steelcasing@0"
            ]
        },
        {
            "x": 0,
            "y": 3,
            "z": 3,
            "elements": [
                "contenttweaker:steelcasing@0"
            ]
        },
        {
            "x": -1,
            "y": 1,
            "z": 2,
            "elements": [
                "contenttweaker:steelcasing@0"
            ]
        },
        {
            "x": 0,
            "y": 1,
            "z": 2,
            "elements": [
                "contenttweaker:steelcasing@0"
            ]
        },
        {
            "x": 0,
            "y": 1,
            "z": -1,
            "elements": [
                "contenttweaker:steelcasing@0"
            ]
        },
        {
            "x": 1,
            "y": 1,
            "z": 2,
            "elements": [
                "contenttweaker:steelcasing@0"
            ]
        },
        {
            "x": 0,
            "y": 9,
            "z": -1,
            "elements": [
                "contenttweaker:steelcasing@0"
            ]
        },
        {
            "x": -1,
            "y": 16,
            "z": 1,
            "elements": [
                "modularmachinery:blockfluidinputhatch"
            ]
        },
        {
            "x": -1,
            "y": 14,
            "z": 0,
            "elements": [
                "contenttweaker:steelcasing@0"
            ]
        },
        {
            "x": 0,
            "y": 16,
            "z": 1,
            "elements": [
                "modularmachinery:blockcasing@1"
            ]
        },
        {
            "x": 1,
            "y": 16,
            "z": 1,
            "elements": [
                "modularmachinery:blockfluidinputhatch"
            ]
        },
        {
            "x": 0,
            "y": 14,
            "z": 0,
            "elements": [
                "contenttweaker:reactorinternal@0"
            ]
        },
        {
            "x": 1,
            "y": 14,
            "z": 0,
            "elements": [
                "contenttweaker:steelcasing@0"
            ]
        },
        {
            "x": 0,
            "y": 12,
            "z": 3,
            "elements": [
                "contenttweaker:steelcasing@0"
            ]
        },
        {
            "x": -2,
            "y": 8,
            "z": 1,
            "elements": [
                "contenttweaker:steelcasing@0"
            ]
        },
        {
            "x": -1,
            "y": 10,
            "z": 2,
            "elements": [
                "contenttweaker:steelcasing@0"
            ]
        },
        {
            "x": -1,
            "y": 6,
            "z": 0,
            "elements": [
                "contenttweaker:steelcasing@0"
            ]
        },
        {
            "x": 1,
            "y": 10,
            "z": 2,
            "elements": [
                "contenttweaker:steelcasing@0"
            ]
        },
        {
            "x": 0,
            "y": 8,
            "z": 1,
            "elements": [
                "casings_catalyst"
            ]
        },
        {
            "x": 2,
            "y": 8,
            "z": 1,
            "elements": [
                "contenttweaker:steelcasing@0"
            ]
        },
        {
            "x": 1,
            "y": 6,
            "z": 0,
            "elements": [
                "contenttweaker:steelcasing@0"
            ]
        },
        {
            "x": 2,
            "y": 0,
            "z": -1,
            "elements": [
                "industrialrenewal:catwalk_steel_pillar@0"
            ]
        },
        {
            "x": 0,
            "y": 4,
            "z": 3,
            "elements": [
                "contenttweaker:steelcasing@0"
            ]
        },
        {
            "x": -2,
            "y": 0,
            "z": 1,
            "elements": [
                "industrialrenewal:catwalk_column_steel@0"
            ]
        },
        {
            "x": -1,
            "y": 2,
            "z": 2,
            "elements": [
                "contenttweaker:steelcasing@0"
            ]
        },
        {
            "x": 1,
            "y": 0,
            "z": -1,
            "elements": [
                "industrialrenewal:catwalk_column_steel@0"
            ]
        },
        {
            "x": 0,
            "y": 0,
            "z": -1,
            "elements": [
                "industrialrenewal:catwalk_column_steel@0"
            ]
        },
        {
            "x": 0,
            "y": 2,
            "z": 2,
            "elements": [
                "contenttweaker:reactorinternal@0"
            ]
        },
        {
            "x": -1,
            "y": 0,
            "z": 1,
            "elements": [
                "contenttweaker:steelcasing@0"
            ]
        },
        {
            "x": 0,
            "y": 0,
            "z": 1,
            "elements": [
                "modularmachinery:blockfluidoutputhatch"
            ]
        },
        {
            "x": -1,
            "y": 0,
            "z": -1,
            "elements": [
                "industrialrenewal:catwalk_column_steel@0"
            ]
        },
        {
            "x": 1,
            "y": 2,
            "z": 2,
            "elements": [
                "contenttweaker:steelcasing@0"
            ]
        },
        {
            "x": -2,
            "y": 0,
            "z": -1,
            "elements": [
                "industrialrenewal:catwalk_steel_pillar@0"
            ]
        },
        {
            "x": 1,
            "y": 0,
            "z": 1,
            "elements": [
                "contenttweaker:steelcasing@0"
            ]
        },
        {
            "x": 2,
            "y": 0,
            "z": 1,
            "elements": [
                "industrialrenewal:catwalk_column_steel@0"
            ]
        },
        {
            "x": 0,
            "y": 8,
            "z": -1,
            "elements": [
                "contenttweaker:steelcasing@0"
            ]
        },
        {
            "x": -1,
            "y": 15,
            "z": 0,
            "elements": [
                "contenttweaker:steelcasing@0"
            ]
        },
        {
            "x": 0,
            "y": 15,
            "z": 0,
            "elements": [
                "contenttweaker:steelcasing@0"
            ]
        },
        {
            "x": 1,
            "y": 15,
            "z": 0,
            "elements": [
                "contenttweaker:steelcasing@0"
            ]
        },
        {
            "x": -2,
            "y": 9,
            "z": 1,
            "elements": [
                "contenttweaker:steelcasing@0"
            ]
        },
        {
            "x": -1,
            "y": 11,
            "z": 2,
            "elements": [
                "contenttweaker:steelcasing@0"
            ]
        },
        {
            "x": 0,
            "y": 13,
            "z": 3,
            "elements": [
                "contenttweaker:steelcasing@0"
            ]
        },
        {
            "x": 1,
            "y": 11,
            "z": 2,
            "elements": [
                "contenttweaker:steelcasing@0"
            ]
        },
        {
            "x": 0,
            "y": 9,
            "z": 1,
            "elements": [
                "casings_catalyst"
            ]
        },
        {
            "x": -1,
            "y": 7,
            "z": 0,
            "elements": [
                "contenttweaker:steelcasing@0"
            ]
        },
        {
            "x": 2,
            "y": 9,
            "z": 1,
            "elements": [
                "contenttweaker:steelcasing@0"
            ]
        },
        {
            "x": 1,
            "y": 7,
            "z": 0,
            "elements": [
                "contenttweaker:steelcasing@0"
            ]
        },
        {
            "x": 2,
            "y": -1,
            "z": -1,
            "elements": [
                "industrialrenewal:catwalk_steel_pillar@0"
            ]
        },
        {
            "x": -2,
            "y": 1,
            "z": 1,
            "elements": [
                "contenttweaker:steelcasing@0"
            ]
        },
        {
            "x": -1,
            "y": 3,
            "z": 2,
            "elements": [
                "contenttweaker:steelcasing@0"
            ]
        },
        {
            "x": 0,
            "y": 5,
            "z": 3,
            "elements": [
                "contenttweaker:steelcasing@0"
            ]
        },
        {
            "x": -1,
            "y": 1,
            "z": 1,
            "elements": [
                "contenttweaker:steelcasing@0"
            ]
        },
        {
            "x": 1,
            "y": 3,
            "z": 2,
            "elements": [
                "contenttweaker:steelcasing@0"
            ]
        },
        {
            "x": -2,
            "y": -1,
            "z": -1,
            "elements": [
                "industrialrenewal:catwalk_steel_pillar@0"
            ]
        },
        {
            "x": 1,
            "y": 1,
            "z": 1,
            "elements": [
                "contenttweaker:steelcasing@0"
            ]
        },
        {
            "x": 2,
            "y": 1,
            "z": 1,
            "elements": [
                "contenttweaker:steelcasing@0"
            ]
        },
        {
            "x": 0,
            "y": 7,
            "z": -1,
            "elements": [
                "contenttweaker:steelcasing@0"
            ]
        },
        {
            "x": 0,
            "y": 15,
            "z": -1,
            "elements": [
                "contenttweaker:steelcasing@0"
            ]
        },
        {
            "x": 0,
            "y": 16,
            "z": 0,
            "elements": [
                "contenttweaker:steelcasing@0"
            ]
        },
        {
            "x": -2,
            "y": 10,
            "z": 1,
            "elements": [
                "contenttweaker:steelcasing@0"
            ]
        },
        {
            "x": -1,
            "y": 12,
            "z": 2,
            "elements": [
                "contenttweaker:steelcasing@0"
            ]
        },
        {
            "x": 0,
            "y": 14,
            "z": 3,
            "elements": [
                "contenttweaker:steelcasing@0"
            ]
        },
        {
            "x": 1,
            "y": 12,
            "z": 2,
            "elements": [
                "contenttweaker:steelcasing@0"
            ]
        },
        {
            "x": -1,
            "y": 8,
            "z": 0,
            "elements": [
                "contenttweaker:steelcasing@0"
            ]
        },
        {
            "x": 2,
            "y": 10,
            "z": 1,
            "elements": [
                "contenttweaker:steelcasing@0"
            ]
        },
        {
            "x": 1,
            "y": 8,
            "z": 0,
            "elements": [
                "contenttweaker:steelcasing@0"
            ]
        },
        {
            "x": 2,
            "y": -2,
            "z": -1,
            "elements": [
                "industrialrenewal:catwalk_steel_pillar@0"
            ]
        },
        {
            "x": -2,
            "y": 2,
            "z": 1,
            "elements": [
                "contenttweaker:steelcasing@0"
            ]
        },
        {
            "x": -1,
            "y": 4,
            "z": 2,
            "elements": [
                "contenttweaker:steelcasing@0"
            ]
        },
        {
            "x": 0,
            "y": 6,
            "z": 3,
            "elements": [
                "contenttweaker:steelcasing@0"
            ]
        },
        {
            "x": -1,
            "y": 2,
            "z": 1,
            "elements": [
                "contenttweaker:reactorinternal@0"
            ]
        },
        {
            "x": 1,
            "y": 4,
            "z": 2,
            "elements": [
                "contenttweaker:steelcasing@0"
            ]
        },
        {
            "x": 0,
            "y": 2,
            "z": 1,
            "elements": [
                "contenttweaker:reactorinternal@0"
            ]
        }
    ]}