{
    "registryname": "regeneratormedium",
    "localizedname": "Catalyst Regenerator (Medium)",
    "color": "F3FAFF",
    "parts": [
        {
            "x": 3,
            "y": 6,
            "z": 3,
            "elements": [
                "immersiveengineering:sheetmetal@1"
            ]
        },
        {
            "x": 2,
            "y": 4,
            "z": 2,
            "elements": [
                "immersiveengineering:sheetmetal@1"
            ]
        },
        {
            "x": 1,
            "y": 2,
            "z": 1,
            "elements": [
                "immersiveengineering:sheetmetal@1"
            ]
        },
        {
            "x": 1,
            "y": 10,
            "z": -3,
            "elements": [
                "immersiveengineering:sheetmetal@1"
            ]
        },
        {
            "x": 0,
            "y": 10,
            "z": -3,
            "elements": [
                "immersiveengineering:sheetmetal@1"
            ]
        },
        {
            "x": -1,
            "y": 10,
            "z": -3,
            "elements": [
                "immersiveengineering:sheetmetal@1"
            ]
        },
        {
            "x": -3,
            "y": 7,
            "z": 3,
            "elements": [
                "immersiveengineering:sheetmetal@1"
            ]
        },
        {
            "x": -2,
            "y": 9,
            "z": 4,
            "elements": [
                "immersiveengineering:sheetmetal@1"
            ]
        },
        {
            "x": -3,
            "y": 5,
            "z": 2,
            "elements": [
                "immersiveengineering:sheetmetal@1"
            ]
        },
        {
            "x": 2,
            "y": 9,
            "z": 4,
            "elements": [
                "immersiveengineering:sheetmetal@1"
            ]
        },
        {
            "x": -1,
            "y": 3,
            "z": 1,
            "elements": [
                "immersiveengineering:sheetmetal@1"
            ]
        },
        {
            "x": -1,
            "y": 1,
            "z": 0,
            "elements": [
                "immersiveengineering:sheetmetal@1"
            ]
        },
        {
            "x": 3,
            "y": 7,
            "z": 3,
            "elements": [
                "immersiveengineering:sheetmetal@1"
            ]
        },
        {
            "x": 1,
            "y": 3,
            "z": 1,
            "elements": [
                "immersiveengineering:sheetmetal@1"
            ]
        },
        {
            "x": 0,
            "y": 1,
            "z": 0,
            "elements": [
                "immersiveengineering:sheetmetal@1"
            ]
        },
        {
            "x": 3,
            "y": 5,
            "z": 2,
            "elements": [
                "immersiveengineering:sheetmetal@1"
            ]
        },
        {
            "x": 1,
            "y": 1,
            "z": 0,
            "elements": [
                "immersiveengineering:sheetmetal@1"
            ]
        },
        {
            "x": 1,
            "y": 9,
            "z": -3,
            "elements": [
                "immersiveengineering:sheetmetal@1"
            ]
        },
        {
            "x": 1,
            "y": 11,
            "z": -2,
            "elements": [
                "immersiveengineering:sheetmetal@1"
            ]
        },
        {
            "x": 0,
            "y": 9,
            "z": -3,
            "elements": [
                "immersiveengineering:sheetmetal@1"
            ]
        },
        {
            "x": -1,
            "y": 9,
            "z": -3,
            "elements": [
                "immersiveengineering:sheetmetal@1"
            ]
        },
        {
            "x": 0,
            "y": 11,
            "z": -2,
            "elements": [
                "immersiveengineering:sheetmetal@1"
            ]
        },
        {
            "x": -1,
            "y": 11,
            "z": -2,
            "elements": [
                "immersiveengineering:sheetmetal@1"
            ]
        },
        {
            "x": -4,
            "y": 6,
            "z": 2,
            "elements": [
                "immersiveengineering:sheetmetal@1"
            ]
        },
        {
            "x": -3,
            "y": 8,
            "z": 3,
            "elements": [
                "immersiveengineering:sheetmetal@1"
            ]
        },
        {
            "x": -2,
            "y": 10,
            "z": 4,
            "elements": [
                "immersiveengineering:sheetmetal@1"
            ]
        },
        {
            "x": 0,
            "y": 8,
            "z": 3,
            "elements": [
                "contenttweaker:reactorinternal@0"
            ]
        },
        {
            "x": -2,
            "y": 4,
            "z": 1,
            "elements": [
                "immersiveengineering:sheetmetal@1"
            ]
        },
        {
            "x": 2,
            "y": 10,
            "z": 4,
            "elements": [
                "immersiveengineering:sheetmetal@1"
            ]
        },
        {
            "x": -1,
            "y": 4,
            "z": 1,
            "elements": [
                "immersiveengineering:sheetmetal@1"
            ]
        },
        {
            "x": -1,
            "y": 2,
            "z": 0,
            "elements": [
                "immersiveengineering:sheetmetal@1"
            ]
        },
        {
            "x": 3,
            "y": 8,
            "z": 3,
            "elements": [
                "immersiveengineering:sheetmetal@1"
            ]
        },
        {
            "x": 1,
            "y": 4,
            "z": 1,
            "elements": [
                "immersiveengineering:sheetmetal@1"
            ]
        },
        {
            "x": 0,
            "y": 2,
            "z": 0,
            "elements": [
                "immersiveengineering:sheetmetal@1"
            ]
        },
        {
            "x": 2,
            "y": 4,
            "z": 1,
            "elements": [
                "immersiveengineering:sheetmetal@1"
            ]
        },
        {
            "x": 1,
            "y": 2,
            "z": 0,
            "elements": [
                "immersiveengineering:sheetmetal@1"
            ]
        },
        {
            "x": 4,
            "y": 6,
            "z": 2,
            "elements": [
                "immersiveengineering:sheetmetal@1"
            ]
        },
        {
            "x": 2,
            "y": 10,
            "z": -2,
            "elements": [
                "immersiveengineering:sheetmetal@1"
            ]
        },
        {
            "x": 1,
            "y": 8,
            "z": -3,
            "elements": [
                "immersiveengineering:sheetmetal@1"
            ]
        },
        {
            "x": 0,
            "y": 8,
            "z": -3,
            "elements": [
                "immersiveengineering:sheetmetal@1"
            ]
        },
        {
            "x": -1,
            "y": 8,
            "z": -3,
            "elements": [
                "immersiveengineering:sheetmetal@1"
            ]
        },
        {
            "x": 1,
            "y": 12,
            "z": -1,
            "elements": [
                "immersiveengineering:sheetmetal@1"
            ]
        },
        {
            "x": 0,
            "y": 12,
            "z": -1,
            "elements": [
                "immersiveengineering:sheetmetal@1"
            ]
        },
        {
            "x": -2,
            "y": 10,
            "z": -2,
            "elements": [
                "immersiveengineering:sheetmetal@1"
            ]
        },
        {
            "x": -1,
            "y": 12,
            "z": -1,
            "elements": [
                "immersiveengineering:sheetmetal@1"
            ]
        },
        {
            "x": -4,
            "y": 7,
            "z": 2,
            "elements": [
                "immersiveengineering:sheetmetal@1"
            ]
        },
        {
            "x": -3,
            "y": 9,
            "z": 3,
            "elements": [
                "immersiveengineering:sheetmetal@1"
            ]
        },
        {
            "x": -1,
            "y": 11,
            "z": 4,
            "elements": [
                "immersiveengineering:sheetmetal@1"
            ]
        },
        {
            "x": -3,
            "y": 5,
            "z": 1,
            "elements": [
                "immersiveengineering:sheetmetal@1"
            ]
        },
        {
            "x": 0,
            "y": 11,
            "z": 4,
            "elements": [
                "immersiveengineering:sheetmetal@1"
            ]
        },
        {
            "x": 1,
            "y": 11,
            "z": 4,
            "elements": [
                "immersiveengineering:sheetmetal@1"
            ]
        },
        {
            "x": 0,
            "y": 9,
            "z": 3,
            "elements": [
                "contenttweaker:reactorinternal@0"
            ]
        },
        {
            "x": -1,
            "y": 3,
            "z": 0,
            "elements": [
                "immersiveengineering:sheetmetal@1"
            ]
        },
        {
            "x": 3,
            "y": 9,
            "z": 3,
            "elements": [
                "immersiveengineering:sheetmetal@1"
            ]
        },
        {
            "x": 0,
            "y": 3,
            "z": 0,
            "elements": [
                "immersiveengineering:sheetmetal@1"
            ]
        },
        {
            "x": 1,
            "y": 3,
            "z": 0,
            "elements": [
                "immersiveengineering:sheetmetal@1"
            ]
        },
        {
            "x": 4,
            "y": 7,
            "z": 2,
            "elements": [
                "immersiveengineering:sheetmetal@1"
            ]
        },
        {
            "x": 3,
            "y": 5,
            "z": 1,
            "elements": [
                "immersiveengineering:sheetmetal@1"
            ]
        },
        {
            "x": 2,
            "y": 9,
            "z": -2,
            "elements": [
                "immersiveengineering:sheetmetal@1"
            ]
        },
        {
            "x": 1,
            "y": 7,
            "z": -3,
            "elements": [
                "immersiveengineering:sheetmetal@1"
            ]
        },
        {
            "x": 2,
            "y": 11,
            "z": -1,
            "elements": [
                "immersiveengineering:sheetmetal@1"
            ]
        },
        {
            "x": 0,
            "y": 7,
            "z": -3,
            "elements": [
                "modularmachinery:blockinputbus"
            ]
        },
        {
            "x": -1,
            "y": 7,
            "z": -3,
            "elements": [
                "immersiveengineering:sheetmetal@1"
            ]
        },
        {
            "x": 0,
            "y": 11,
            "z": -1,
            "elements": [
                "contenttweaker:reactorinternal@0"
            ]
        },
        {
            "x": -2,
            "y": 9,
            "z": -2,
            "elements": [
                "immersiveengineering:sheetmetal@1"
            ]
        },
        {
            "x": -2,
            "y": 11,
            "z": -1,
            "elements": [
                "immersiveengineering:sheetmetal@1"
            ]
        },
        {
            "x": -4,
            "y": 8,
            "z": 2,
            "elements": [
                "immersiveengineering:sheetmetal@1"
            ]
        },
        {
            "x": -3,
            "y": 10,
            "z": 3,
            "elements": [
                "immersiveengineering:sheetmetal@1"
            ]
        },
        {
            "x": -4,
            "y": 6,
            "z": 1,
            "elements": [
                "immersiveengineering:sheetmetal@1"
            ]
        },
        {
            "x": 0,
            "y": 10,
            "z": 3,
            "elements": [
                "contenttweaker:reactorinternal@0"
            ]
        },
        {
            "x": -2,
            "y": 4,
            "z": 0,
            "elements": [
                "immersiveengineering:sheetmetal@1"
            ]
        },
        {
            "x": -1,
            "y": 4,
            "z": 0,
            "elements": [
                "immersiveengineering:sheetmetal@1"
            ]
        },
        {
            "x": 3,
            "y": 10,
            "z": 3,
            "elements": [
                "immersiveengineering:sheetmetal@1"
            ]
        },
        {
            "x": 0,
            "y": 4,
            "z": 0,
            "elements": [
                "immersiveengineering:sheetmetal@1"
            ]
        },
        {
            "x": 1,
            "y": 4,
            "z": 0,
            "elements": [
                "immersiveengineering:sheetmetal@1"
            ]
        },
        {
            "x": 4,
            "y": 8,
            "z": 2,
            "elements": [
                "immersiveengineering:sheetmetal@1"
            ]
        },
        {
            "x": 2,
            "y": 4,
            "z": 0,
            "elements": [
                "immersiveengineering:sheetmetal@1"
            ]
        },
        {
            "x": 4,
            "y": 6,
            "z": 1,
            "elements": [
                "immersiveengineering:sheetmetal@1"
            ]
        },
        {
            "x": 3,
            "y": 10,
            "z": -1,
            "elements": [
                "immersiveengineering:sheetmetal@1"
            ]
        },
        {
            "x": 2,
            "y": 8,
            "z": -2,
            "elements": [
                "immersiveengineering:sheetmetal@1"
            ]
        },
        {
            "x": 1,
            "y": 6,
            "z": -3,
            "elements": [
                "immersiveengineering:sheetmetal@1"
            ]
        },
        {
            "x": 0,
            "y": 6,
            "z": -3,
            "elements": [
                "immersiveengineering:sheetmetal@1"
            ]
        },
        {
            "x": -1,
            "y": 6,
            "z": -3,
            "elements": [
                "immersiveengineering:sheetmetal@1"
            ]
        },
        {
            "x": 0,
            "y": 10,
            "z": -1,
            "elements": [
                "contenttweaker:reactorinternal@0"
            ]
        },
        {
            "x": -2,
            "y": 8,
            "z": -2,
            "elements": [
                "immersiveengineering:sheetmetal@1"
            ]
        },
        {
            "x": -3,
            "y": 10,
            "z": -1,
            "elements": [
                "immersiveengineering:sheetmetal@1"
            ]
        },
        {
            "x": -4,
            "y": 9,
            "z": 2,
            "elements": [
                "immersiveengineering:sheetmetal@1"
            ]
        },
        {
            "x": -4,
            "y": 7,
            "z": 1,
            "elements": [
                "immersiveengineering:sheetmetal@1"
            ]
        },
        {
            "x": -2,
            "y": 11,
            "z": 3,
            "elements": [
                "immersiveengineering:sheetmetal@1"
            ]
        },
        {
            "x": -3,
            "y": 5,
            "z": 0,
            "elements": [
                "immersiveengineering:sheetmetal@1"
            ]
        },
        {
            "x": 0,
            "y": 11,
            "z": 3,
            "elements": [
                "contenttweaker:reactorinternal@0"
            ]
        },
        {
            "x": 2,
            "y": 11,
            "z": 3,
            "elements": [
                "immersiveengineering:sheetmetal@1"
            ]
        },
        {
            "x": 4,
            "y": 9,
            "z": 2,
            "elements": [
                "immersiveengineering:sheetmetal@1"
            ]
        },
        {
            "x": 4,
            "y": 7,
            "z": 1,
            "elements": [
                "immersiveengineering:sheetmetal@1"
            ]
        },
        {
            "x": 3,
            "y": 5,
            "z": 0,
            "elements": [
                "immersiveengineering:sheetmetal@1"
            ]
        },
        {
            "x": 3,
            "y": 9,
            "z": -1,
            "elements": [
                "immersiveengineering:sheetmetal@1"
            ]
        },
        {
            "x": 2,
            "y": 7,
            "z": -2,
            "elements": [
                "immersiveengineering:sheetmetal@1"
            ]
        },
        {
            "x": 0,
            "y": 9,
            "z": -1,
            "elements": [
                "contenttweaker:reactorinternal@0"
            ]
        },
        {
            "x": -2,
            "y": 7,
            "z": -2,
            "elements": [
                "immersiveengineering:sheetmetal@1"
            ]
        },
        {
            "x": -3,
            "y": 9,
            "z": -1,
            "elements": [
                "immersiveengineering:sheetmetal@1"
            ]
        },
        {
            "x": -4,
            "y": 10,
            "z": 2,
            "elements": [
                "immersiveengineering:sheetmetal@1"
            ]
        },
        {
            "x": -4,
            "y": 8,
            "z": 1,
            "elements": [
                "immersiveengineering:sheetmetal@1"
            ]
        },
        {
            "x": -4,
            "y": 6,
            "z": 0,
            "elements": [
                "immersiveengineering:sheetmetal@1"
            ]
        },
        {
            "x": -1,
            "y": 12,
            "z": 3,
            "elements": [
                "immersiveengineering:sheetmetal@1"
            ]
        },
        {
            "x": -2,
            "y": 8,
            "z": 1,
            "elements": [
                "contenttweaker:reactorinternal@0"
            ]
        },
        {
            "x": 0,
            "y": 12,
            "z": 3,
            "elements": [
                "immersiveengineering:sheetmetal@1"
            ]
        },
        {
            "x": 1,
            "y": 12,
            "z": 3,
            "elements": [
                "immersiveengineering:sheetmetal@1"
            ]
        },
        {
            "x": 0,
            "y": 8,
            "z": 1,
            "elements": [
                "contenttweaker:reactorinternal@0"
            ]
        },
        {
            "x": 2,
            "y": 8,
            "z": 1,
            "elements": [
                "contenttweaker:reactorinternal@0"
            ]
        },
        {
            "x": 4,
            "y": 10,
            "z": 2,
            "elements": [
                "immersiveengineering:sheetmetal@1"
            ]
        },
        {
            "x": 4,
            "y": 8,
            "z": 1,
            "elements": [
                "immersiveengineering:sheetmetal@1"
            ]
        },
        {
            "x": 4,
            "y": 6,
            "z": 0,
            "elements": [
                "immersiveengineering:sheetmetal@1"
            ]
        },
        {
            "x": 3,
            "y": 8,
            "z": -1,
            "elements": [
                "immersiveengineering:sheetmetal@1"
            ]
        },
        {
            "x": 2,
            "y": 6,
            "z": -2,
            "elements": [
                "immersiveengineering:sheetmetal@1"
            ]
        },
        {
            "x": 0,
            "y": 8,
            "z": -1,
            "elements": [
                "contenttweaker:reactorinternal@0"
            ]
        },
        {
            "x": -2,
            "y": 6,
            "z": -2,
            "elements": [
                "immersiveengineering:sheetmetal@1"
            ]
        },
        {
            "x": -3,
            "y": 8,
            "z": -1,
            "elements": [
                "immersiveengineering:sheetmetal@1"
            ]
        },
        {
            "x": -4,
            "y": 9,
            "z": 1,
            "elements": [
                "immersiveengineering:sheetmetal@1"
            ]
        },
        {
            "x": -3,
            "y": 11,
            "z": 2,
            "elements": [
                "immersiveengineering:sheetmetal@1"
            ]
        },
        {
            "x": -4,
            "y": 7,
            "z": 0,
            "elements": [
                "immersiveengineering:sheetmetal@1"
            ]
        },
        {
            "x": -2,
            "y": 9,
            "z": 1,
            "elements": [
                "contenttweaker:reactorinternal@0"
            ]
        },
        {
            "x": 0,
            "y": 9,
            "z": 1,
            "elements": [
                "contenttweaker:reactorinternal@0"
            ]
        },
        {
            "x": 3,
            "y": 11,
            "z": 2,
            "elements": [
                "immersiveengineering:sheetmetal@1"
            ]
        },
        {
            "x": 2,
            "y": 9,
            "z": 1,
            "elements": [
                "contenttweaker:reactorinternal@0"
            ]
        },
        {
            "x": 4,
            "y": 9,
            "z": 1,
            "elements": [
                "immersiveengineering:sheetmetal@1"
            ]
        },
        {
            "x": 4,
            "y": 7,
            "z": 0,
            "elements": [
                "immersiveengineering:sheetmetal@1"
            ]
        },
        {
            "x": 3,
            "y": 7,
            "z": -1,
            "elements": [
                "immersiveengineering:sheetmetal@1"
            ]
        },
        {
            "x": 1,
            "y": 5,
            "z": -2,
            "elements": [
                "immersiveengineering:sheetmetal@1"
            ]
        },
        {
            "x": 0,
            "y": 5,
            "z": -2,
            "elements": [
                "immersiveengineering:sheetmetal@1"
            ]
        },
        {
            "x": -1,
            "y": 5,
            "z": -2,
            "elements": [
                "immersiveengineering:sheetmetal@1"
            ]
        },
        {
            "x": -3,
            "y": 7,
            "z": -1,
            "elements": [
                "immersiveengineering:sheetmetal@1"
            ]
        },
        {
            "x": -4,
            "y": 10,
            "z": 1,
            "elements": [
                "immersiveengineering:sheetmetal@1"
            ]
        },
        {
            "x": -4,
            "y": 8,
            "z": 0,
            "elements": [
                "immersiveengineering:sheetmetal@1"
            ]
        },
        {
            "x": -2,
            "y": 12,
            "z": 2,
            "elements": [
                "immersiveengineering:sheetmetal@1"
            ]
        },
        {
            "x": -2,
            "y": 10,
            "z": 1,
            "elements": [
                "contenttweaker:reactorinternal@0"
            ]
        },
        {
            "x": -1,
            "y": 12,
            "z": 2,
            "elements": [
                "immersiveengineering:sheetmetal@1"
            ]
        },
        {
            "x": 0,
            "y": 12,
            "z": 2,
            "elements": [
                "immersiveengineering:sheetmetal@1"
            ]
        },
        {
            "x": 1,
            "y": 12,
            "z": 2,
            "elements": [
                "immersiveengineering:sheetmetal@1"
            ]
        },
        {
            "x": 0,
            "y": 10,
            "z": 1,
            "elements": [
                "contenttweaker:reactorinternal@0"
            ]
        },
        {
            "x": 2,
            "y": 12,
            "z": 2,
            "elements": [
                "immersiveengineering:sheetmetal@1"
            ]
        },
        {
            "x": 2,
            "y": 10,
            "z": 1,
            "elements": [
                "contenttweaker:reactorinternal@0"
            ]
        },
        {
            "x": 4,
            "y": 10,
            "z": 1,
            "elements": [
                "immersiveengineering:sheetmetal@1"
            ]
        },
        {
            "x": 4,
            "y": 8,
            "z": 0,
            "elements": [
                "immersiveengineering:sheetmetal@1"
            ]
        },
        {
            "x": 3,
            "y": 6,
            "z": -1,
            "elements": [
                "immersiveengineering:sheetmetal@1"
            ]
        },
        {
            "x": -3,
            "y": 6,
            "z": -1,
            "elements": [
                "immersiveengineering:sheetmetal@1"
            ]
        },
        {
            "x": -4,
            "y": 9,
            "z": 0,
            "elements": [
                "immersiveengineering:sheetmetal@1"
            ]
        },
        {
            "x": -3,
            "y": 11,
            "z": 1,
            "elements": [
                "immersiveengineering:sheetmetal@1"
            ]
        },
        {
            "x": -2,
            "y": 11,
            "z": 1,
            "elements": [
                "contenttweaker:reactorinternal@0"
            ]
        },
        {
            "x": 0,
            "y": 11,
            "z": 1,
            "elements": [
                "contenttweaker:reactorinternal@0"
            ]
        },
        {
            "x": 2,
            "y": 11,
            "z": 1,
            "elements": [
                "contenttweaker:reactorinternal@0"
            ]
        },
        {
            "x": 3,
            "y": 11,
            "z": 1,
            "elements": [
                "immersiveengineering:sheetmetal@1"
            ]
        },
        {
            "x": 4,
            "y": 9,
            "z": 0,
            "elements": [
                "immersiveengineering:sheetmetal@1"
            ]
        },
        {
            "x": 2,
            "y": 5,
            "z": -1,
            "elements": [
                "immersiveengineering:sheetmetal@1"
            ]
        },
        {
            "x": -2,
            "y": 5,
            "z": -1,
            "elements": [
                "immersiveengineering:sheetmetal@1"
            ]
        },
        {
            "x": -4,
            "y": 10,
            "z": 0,
            "elements": [
                "immersiveengineering:sheetmetal@1"
            ]
        },
        {
            "x": -2,
            "y": 12,
            "z": 1,
            "elements": [
                "immersiveengineering:sheetmetal@1"
            ]
        },
        {
            "x": -1,
            "y": 12,
            "z": 1,
            "elements": [
                "immersiveengineering:sheetmetal@1"
            ]
        },
        {
            "x": 0,
            "y": 12,
            "z": 1,
            "elements": [
                "modularmachinery:blockfluidoutputhatch"
            ]
        },
        {
            "x": 1,
            "y": 12,
            "z": 1,
            "elements": [
                "immersiveengineering:sheetmetal@1"
            ]
        },
        {
            "x": 2,
            "y": 12,
            "z": 1,
            "elements": [
                "immersiveengineering:sheetmetal@1"
            ]
        },
        {
            "x": 4,
            "y": 10,
            "z": 0,
            "elements": [
                "immersiveengineering:sheetmetal@1"
            ]
        },
        {
            "x": 1,
            "y": 4,
            "z": -1,
            "elements": [
                "immersiveengineering:sheetmetal@1"
            ]
        },
        {
            "x": 0,
            "y": 4,
            "z": -1,
            "elements": [
                "immersiveengineering:sheetmetal@1"
            ]
        },
        {
            "x": -1,
            "y": 4,
            "z": -1,
            "elements": [
                "immersiveengineering:sheetmetal@1"
            ]
        },
        {
            "x": -3,
            "y": 11,
            "z": 0,
            "elements": [
                "immersiveengineering:sheetmetal@1"
            ]
        },
        {
            "x": 3,
            "y": 11,
            "z": 0,
            "elements": [
                "immersiveengineering:sheetmetal@1"
            ]
        },
        {
            "x": -2,
            "y": 12,
            "z": 0,
            "elements": [
                "immersiveengineering:sheetmetal@1"
            ]
        },
        {
            "x": -1,
            "y": 12,
            "z": 0,
            "elements": [
                "immersiveengineering:sheetmetal@1"
            ]
        },
        {
            "x": 0,
            "y": 12,
            "z": 0,
            "elements": [
                "immersiveengineering:sheetmetal@1"
            ]
        },
        {
            "x": 1,
            "y": 12,
            "z": 0,
            "elements": [
                "immersiveengineering:sheetmetal@1"
            ]
        },
        {
            "x": 2,
            "y": 12,
            "z": 0,
            "elements": [
                "immersiveengineering:sheetmetal@1"
            ]
        },
        {
            "x": -1,
            "y": 6,
            "z": 5,
            "elements": [
                "immersiveengineering:sheetmetal@1"
            ]
        },
        {
            "x": 0,
            "y": 6,
            "z": 5,
            "elements": [
                "immersiveengineering:sheetmetal@1"
            ]
        },
        {
            "x": 1,
            "y": 6,
            "z": 5,
            "elements": [
                "immersiveengineering:sheetmetal@1"
            ]
        },
        {
            "x": 0,
            "y": 0,
            "z": 2,
            "elements": [
                "immersiveengineering:sheetmetal@1"
            ]
        },
        {
            "x": -1,
            "y": 7,
            "z": 5,
            "elements": [
                "immersiveengineering:sheetmetal@1"
            ]
        },
        {
            "x": 0,
            "y": 7,
            "z": 5,
            "elements": [
                "immersiveengineering:sheetmetal@1"
            ]
        },
        {
            "x": -1,
            "y": 5,
            "z": 4,
            "elements": [
                "immersiveengineering:sheetmetal@1"
            ]
        },
        {
            "x": 1,
            "y": 7,
            "z": 5,
            "elements": [
                "immersiveengineering:sheetmetal@1"
            ]
        },
        {
            "x": 0,
            "y": 5,
            "z": 4,
            "elements": [
                "immersiveengineering:sheetmetal@1"
            ]
        },
        {
            "x": 1,
            "y": 5,
            "z": 4,
            "elements": [
                "immersiveengineering:sheetmetal@1"
            ]
        },
        {
            "x": -1,
            "y": 1,
            "z": 2,
            "elements": [
                "immersiveengineering:sheetmetal@1"
            ]
        },
        {
            "x": 0,
            "y": 1,
            "z": 2,
            "elements": [
                "immersiveengineering:sheetmetal@1"
            ]
        },
        {
            "x": 1,
            "y": 1,
            "z": 2,
            "elements": [
                "immersiveengineering:sheetmetal@1"
            ]
        },
        {
            "x": -2,
            "y": 6,
            "z": 4,
            "elements": [
                "immersiveengineering:sheetmetal@1"
            ]
        },
        {
            "x": -1,
            "y": 8,
            "z": 5,
            "elements": [
                "immersiveengineering:sheetmetal@1"
            ]
        },
        {
            "x": 0,
            "y": 8,
            "z": 5,
            "elements": [
                "immersiveengineering:sheetmetal@1"
            ]
        },
        {
            "x": 1,
            "y": 8,
            "z": 5,
            "elements": [
                "immersiveengineering:sheetmetal@1"
            ]
        },
        {
            "x": -1,
            "y": 4,
            "z": 3,
            "elements": [
                "immersiveengineering:sheetmetal@1"
            ]
        },
        {
            "x": 0,
            "y": 4,
            "z": 3,
            "elements": [
                "immersiveengineering:sheetmetal@1"
            ]
        },
        {
            "x": -1,
            "y": 2,
            "z": 2,
            "elements": [
                "immersiveengineering:sheetmetal@1"
            ]
        },
        {
            "x": 2,
            "y": 6,
            "z": 4,
            "elements": [
                "immersiveengineering:sheetmetal@1"
            ]
        },
        {
            "x": 1,
            "y": 4,
            "z": 3,
            "elements": [
                "immersiveengineering:sheetmetal@1"
            ]
        },
        {
            "x": 0,
            "y": 2,
            "z": 2,
            "elements": [
                "modularmachinery:blockoutputbus"
            ]
        },
        {
            "x": -1,
            "y": 0,
            "z": 1,
            "elements": [
                "immersiveengineering:sheetmetal@1"
            ]
        },
        {
            "x": 0,
            "y": 0,
            "z": 1,
            "elements": [
                "modularmachinery:blockfluidinputhatch"
            ]
        },
        {
            "x": 1,
            "y": 2,
            "z": 2,
            "elements": [
                "immersiveengineering:sheetmetal@1"
            ]
        },
        {
            "x": 1,
            "y": 0,
            "z": 1,
            "elements": [
                "immersiveengineering:sheetmetal@1"
            ]
        },
        {
            "x": -2,
            "y": 7,
            "z": 4,
            "elements": [
                "immersiveengineering:sheetmetal@1"
            ]
        },
        {
            "x": -1,
            "y": 9,
            "z": 5,
            "elements": [
                "immersiveengineering:sheetmetal@1"
            ]
        },
        {
            "x": -2,
            "y": 5,
            "z": 3,
            "elements": [
                "immersiveengineering:sheetmetal@1"
            ]
        },
        {
            "x": 0,
            "y": 9,
            "z": 5,
            "elements": [
                "immersiveengineering:sheetmetal@1"
            ]
        },
        {
            "x": 1,
            "y": 9,
            "z": 5,
            "elements": [
                "immersiveengineering:sheetmetal@1"
            ]
        },
        {
            "x": -1,
            "y": 3,
            "z": 2,
            "elements": [
                "immersiveengineering:sheetmetal@1"
            ]
        },
        {
            "x": 2,
            "y": 7,
            "z": 4,
            "elements": [
                "immersiveengineering:sheetmetal@1"
            ]
        },
        {
            "x": 0,
            "y": 3,
            "z": 2,
            "elements": [
                "immersiveengineering:sheetmetal@1"
            ]
        },
        {
            "x": -1,
            "y": 1,
            "z": 1,
            "elements": [
                "immersiveengineering:sheetmetal@1"
            ]
        },
        {
            "x": 2,
            "y": 5,
            "z": 3,
            "elements": [
                "immersiveengineering:sheetmetal@1"
            ]
        },
        {
            "x": 1,
            "y": 3,
            "z": 2,
            "elements": [
                "immersiveengineering:sheetmetal@1"
            ]
        },
        {
            "x": 0,
            "y": 1,
            "z": 1,
            "elements": [
                "contenttweaker:reactorinternal@0"
            ]
        },
        {
            "x": 1,
            "y": 1,
            "z": 1,
            "elements": [
                "immersiveengineering:sheetmetal@1"
            ]
        },
        {
            "x": -3,
            "y": 6,
            "z": 3,
            "elements": [
                "immersiveengineering:sheetmetal@1"
            ]
        },
        {
            "x": -2,
            "y": 8,
            "z": 4,
            "elements": [
                "immersiveengineering:sheetmetal@1"
            ]
        },
        {
            "x": -1,
            "y": 10,
            "z": 5,
            "elements": [
                "immersiveengineering:sheetmetal@1"
            ]
        },
        {
            "x": 0,
            "y": 10,
            "z": 5,
            "elements": [
                "immersiveengineering:sheetmetal@1"
            ]
        },
        {
            "x": 1,
            "y": 10,
            "z": 5,
            "elements": [
                "immersiveengineering:sheetmetal@1"
            ]
        },
        {
            "x": -2,
            "y": 4,
            "z": 2,
            "elements": [
                "immersiveengineering:sheetmetal@1"
            ]
        },
        {
            "x": -1,
            "y": 4,
            "z": 2,
            "elements": [
                "immersiveengineering:sheetmetal@1"
            ]
        },
        {
            "x": 2,
            "y": 8,
            "z": 4,
            "elements": [
                "immersiveengineering:sheetmetal@1"
            ]
        },
        {
            "x": 0,
            "y": 4,
            "z": 2,
            "elements": [
                "immersiveengineering:sheetmetal@1"
            ]
        },
        {
            "x": -1,
            "y": 2,
            "z": 1,
            "elements": [
                "immersiveengineering:sheetmetal@1"
            ]
        },
        {
            "x": 1,
            "y": 4,
            "z": 2,
            "elements": [
                "immersiveengineering:sheetmetal@1"
            ]
        }
    ]}